Workbook

Sheet Parameters
A1: XFuel C2 — global parameters (inputs)
A3: Scenario name | B3: Base case
A4: Plan start month (YYYY-MM) | B4: 2027-01
A5: Operations start (period index, 0-based) | B5: 18
A6: Corporate income tax rate | B6: 0.25
A7: DSO (days) | B7: 45
A8: DPO (days) | B8: 60
A9: WACC (project discount rate) | B9: 0.09
A10: Cost of equity | B10: 0.15
A11: Exit EV/EBITDA multiple | B11: 8
A12: Opening cash | B12: 0
A13: OPEX inflation (p.a.) | B13: 0.02
A14: Compensation inflation (p.a.) | B14: 0.025
A16: Live workbook: P&L, Cashflow and Summary are Excel formulas driven by the input tabs. Edit an input and Excel recalculates.

Sheet CAPEX
A1: CAPEX — phasing, spend and depreciation
A3: Concept | B3: Jan-27 | C3: Feb-27 | D3: Mar-27 | E3: Apr-27 | F3: May-27 | G3: Jun-27 | H3: Jul-27 | I3: Aug-27 | J3: Sep-27 | K3: Oct-27 | L3: Nov-27 | M3: Dec-27 | N3: Jan-28 | O3: Feb-28 | P3: Mar-28 | Q3: Apr-28 | R3: May-28 | S3: Jun-28 | T3: Jul-28 | U3: Aug-28 | V3: Sep-28 | W3: Oct-28 | X3: Nov-28 | Y3: Dec-28 | Z3: Jan-29 | AA3: Feb-29 | AB3: Mar-29 | AC3: Apr-29 | AD3: May-29 | AE3: Jun-29 | AF3: Jul-29 | AG3: Aug-29 | AH3: Sep-29 | AI3: Oct-29 | AJ3: Nov-29 | AK3: Dec-29 | AL3: Y4 | AM3: Y5 | AN3: Y6 | AO3: Y7 | AP3: Y8 | AQ3: Y9 | AR3: Y10
A4: Months in period | B4: 1 | C4: 1 | D4: 1 | E4: 1 | F4: 1 | G4: 1 | H4: 1 | I4: 1 | J4: 1 | K4: 1 | L4: 1 | M4: 1 | N4: 1 | O4: 1 | P4: 1 | Q4: 1 | R4: 1 | S4: 1 | T4: 1 | U4: 1 | V4: 1 | W4: 1 | X4: 1 | Y4: 1 | Z4: 1 | AA4: 1 | AB4: 1 | AC4: 1 | AD4: 1 | AE4: 1 | AF4: 1 | AG4: 1 | AH4: 1 | AI4: 1 | AJ4: 1 | AK4: 1 | AL4: 12 | AM4: 12 | AN4: 12 | AO4: 12 | AP4: 12 | AQ4: 12 | AR4: 12
A5: Plan year | B5: 1 | C5: 1 | D5: 1 | E5: 1 | F5: 1 | G5: 1 | H5: 1 | I5: 1 | J5: 1 | K5: 1 | L5: 1 | M5: 1 | N5: 2 | O5: 2 | P5: 2 | Q5: 2 | R5: 2 | S5: 2 | T5: 2 | U5: 2 | V5: 2 | W5: 2 | X5: 2 | Y5: 2 | Z5: 3 | AA5: 3 | AB5: 3 | AC5: 3 | AD5: 3 | AE5: 3 | AF5: 3 | AG5: 3 | AH5: 3 | AI5: 3 | AJ5: 3 | AK5: 3 | AL5: 4 | AM5: 5 | AN5: 6 | AO5: 7 | AP5: 8 | AQ5: 9 | AR5: 10
A7: ISBL — process plant — total cost | B7: 13699966
A8: ISBL — process plant — monthly depreciation rate | B8: 0.0055555556
A9: ISBL — process plant — phasing % | B9: 0.02 | C9: 0.03 | D9: 0.04 | E9: 0.05 | F9: 0.06 | G9: 0.07 | H9: 0.08 | I9: 0.08 | J9: 0.08 | K9: 0.08 | L9: 0.08 | M9: 0.07 | N9: 0.07 | O9: 0.06 | P9: 0.05 | Q9: 0.04 | R9: 0.03 | S9: 0.01 | T9: 0 | U9: 0 | V9: 0 | W9: 0 | X9: 0 | Y9: 0 | Z9: 0 | AA9: 0 | AB9: 0 | AC9: 0 | AD9: 0 | AE9: 0 | AF9: 0 | AG9: 0 | AH9: 0 | AI9: 0 | AJ9: 0 | AK9: 0 | AL9: 0 | AM9: 0 | AN9: 0 | AO9: 0 | AP9: 0 | AQ9: 0 | AR9: 0
A10: ISBL — process plant — spend | B10: =$B$7*B9 | C10: =$B$7*C9 | D10: =$B$7*D9 | E10: =$B$7*E9 | F10: =$B$7*F9 | G10: =$B$7*G9 | H10: =$B$7*H9 | I10: =$B$7*I9 | ... AR10: =$B$7*AR9
A11: ISBL — process plant — cumulative cost | B11: =B10 | C11: =B11+C10 | D11: =C11+D10 | E11: =D11+E10 | F11: =E11+F10 | G11: =F11+G10 | H11: =G11+H10 | I11: =H11+I10 | J11: =I11+J10 | ... AR11: =AQ11+AR10
A12: ISBL — process plant — depreciation | B12: =IF(0<'Parameters'!$B$5,0,MAX(0,MIN(B11*$B$8*B4,B11-0))) | C12: =IF(1<'Parameters'!$B$5,0,MAX(0,MIN(C11*$B$8*C4,C11-B13))) | D12: =IF(2<'Parameters'!$B$5,0,MAX(0,MIN(D11*$B$8*D4,D11-C13))) | E12: =IF(3<'Parameters'!$B$5,0,MAX(0,MIN(E11*$B$8*E4,E11-D13))) | F12: =IF(4<'Parameters'!$B$5,0,MAX(0,MIN(F11*$B$8*F4,F11-E13))) | G12: =IF(5<'Parameters'!$B$5,0,MAX(0,MIN(G11*$B$8*G4,G11-F13))) | H12: =IF(6<'Parameters'!$B$5,0,MAX(0,MIN(H11*$B$8*H4,H11-G13))) | I12: =IF(7<'Parameters'!$B$5,0,MAX(0,MIN(I11*$B$8*I4,I11-H13))) | J12: =IF(8<'Parameters'!$B$5,0,MAX(0,MIN(J11*$B$8*J4,J11-I13))) | K12: =IF(9<'Parameters'!$B$5,0,MAX(0,MIN(K11*$B$8*K4,K11-J13))) | L12: =IF(10<'Parameters'!$B$5,0,MAX(0,MIN(L11*$B$8*L4,L11-K13))) | M12: =IF(11<'Parameters'!$B$5,0,MAX(0,MIN(M11*$B$8*M4,M11-L13))) | N12: =IF(12<'Parameters'!$B$5,0,MAX(0,MIN(N11*$B$8*N4,N11-M13))) | O12: =IF(13<'Parameters'!$B$5,0,MAX(0,MIN(O11*$B$8*O4,O11-N13))) | P12: =IF(14<'Parameters'!$B$5,0,MAX(0,MIN(P11*$B$8*P4,P11-O13))) | Q12: =IF(15<'Parameters'!$B$5,0,MAX(0,MIN(Q11*$B$8*Q4,Q11-P13))) | R12: =IF(16<'Parameters'!$B$5,0,MAX(0,MIN(R11*$B$8*R4,R11-Q13))) | S12: =IF(17<'Parameters'!$B$5,0,MAX(0,MIN(S11*$B$8*S4,S11-R13))) | T12: =IF(18<'Parameters'!$B$5,0,MAX(0,MIN(T11*$B$8*T4,T11-S13))) | U12: =IF(19<'Parameters'!$B$5,0,MAX(0,MIN(U11*$B$8*U4,U11-T13))) | V12: =IF(20<'Parameters'!$B$5,0,MAX(0,MIN(V11*$B$8*V4,V11-U13))) | W12: =IF(21<'Parameters'!$B$5,0,MAX(0,MIN(W11*$B$8*W4,W11-V13))) | X12: =IF(22<'Parameters'!$B$5,0,MAX(0,MIN(X11*$B$8*X4,X11-W13))) | Y12: =IF(23<'Parameters'!$B$5,0,MAX(0,MIN(Y11*$B$8*Y4,Y11-X13))) | Z12: =IF(24<'Parameters'!$B$5,0,MAX(0,MIN(Z11*$B$8*Z4,Z11-Y13))) | AA12: =IF(25<'Parameters'!$B$5,0,MAX(0,MIN(AA11*$B$8*AA4,AA11-Z13))) | AB12: =IF(26<'Parameters'!$B$5,0,MAX(0,MIN(AB11*$B$8*AB4,AB11-AA13))) | AC12: =IF(27<'Parameters'!$B$5,0,MAX(0,MIN(AC11*$B$8*AC4,AC11-AB13))) | AD12: =IF(28<'Parameters'!$B$5,0,MAX(0,MIN(AD11*$B$8*AD4,AD11-AC13))) | AE12: =IF(29<'Parameters'!$B$5,0,MAX(0,MIN(AE11*$B$8*AE4,AE11-AD13))) | AF12: =IF(30<'Parameters'!$B$5,0,MAX(0,MIN(AF11*$B$8*AF4,AF11-AE13))) | AG12: =IF(31<'Parameters'!$B$5,0,MAX(0,MIN(AG11*$B$8*AG4,AG11-AF13))) | AH12: =IF(32<'Parameters'!$B$5,0,MAX(0,MIN(AH11*$B$8*AH4,AH11-AG13))) | AI12: =IF(33<'Parameters'!$B$5,0,MAX(0,MIN(AI11*$B$8*AI4,AI11-AH13))) | AJ12: =IF(34<'Parameters'!$B$5,0,MAX(0,MIN(AJ11*$B$8*AJ4,AJ11-AI13))) | AK12: =IF(35<'Parameters'!$B$5,0,MAX(0,MIN(AK11*$B$8*AK4,AK11-AJ13))) | AL12: =IF(36<'Parameters'!$B$5,0,MAX(0,MIN(AL11*$B$8*AL4,AL11-AK13))) | AM12: =IF(37<'Parameters'!$B$5,0,MAX(0,MIN(AM11*$B$8*AM4,AM11-AL13))) | AN12: =IF(38<'Parameters'!$B$5,0,MAX(0,MIN(AN11*$B$8*AN4,AN11-AM13))) | AO12: =IF(39<'Parameters'!$B$5,0,MAX(0,MIN(AO11*$B$8*AO4,AO11-AN13))) | AP12: =IF(40<'Parameters'!$B$5,0,MAX(0,MIN(AP11*$B$8*AP4,AP11-AO13))) | AQ12: =IF(41<'Parameters'!$B$5,0,MAX(0,MIN(AQ11*$B$8*AQ4,AQ11-AP13))) | AR12: =IF(42<'Parameters'!$B$5,0,MAX(0,MIN(AR11*$B$8*AR4,AR11-AQ13)))
A13: ISBL — process plant — accumulated depreciation | B13: =B12 | C13: =B13+C12 | D13: =C13+D12 | E13: =D13+E12 | F13: =E13+F12 | G13: =F13+G12 | H13: =G13+H12 | I13: =H13+I12 | J13: =I13+J12 | ... AR13: =AQ13+AR12
A15: OSBL — infrastructure & civil — total cost | B15: 9578612
A16: OSBL — infrastructure & civil — monthly depreciation rate | B16: 0.0033333333
A17: OSBL — infrastructure & civil — phasing % | B17: 0.02 | C17: 0.03 | D17: 0.04 | E17: 0.05 | F17: 0.06 | G17: 0.07 | H17: 0.08 | I17: 0.08 | J17: 0.08 | K17: 0.08 | L17: 0.08 | M17: 0.07 | N17: 0.07 | O17: 0.06 | P17: 0.05 | Q17: 0.04 | R17: 0.03 | S17: 0.01 | T17: 0 | U17: 0 | V17: 0 | W17: 0 | X17: 0 | Y17: 0 | Z17: 0 | AA17: 0 | AB17: 0 | AC17: 0 | AD17: 0 | AE17: 0 | AF17: 0 | AG17: 0 | AH17: 0 | AI17: 0 | AJ17: 0 | AK17: 0 | AL17: 0 | AM17: 0 | AN17: 0 | AO17: 0 | AP17: 0 | AQ17: 0 | AR17: 0
A18: OSBL — infrastructure & civil — spend | B18: =$B$15*B17 | C18: =$B$15*C17 | D18: =$B$15*D17 | E18: =$B$15*E17 | F18: =$B$15*F17 | G18: =$B$15*G17 | H18: =$B$15*H17 | I18: =$B$15*I17 | ... AR18: =$B$15*AR17
A19: OSBL — infrastructure & civil — cumulative cost | B19: =B18 | C19: =B19+C18 | D19: =C19+D18 | E19: =D19+E18 | F19: =E19+F18 | G19: =F19+G18 | H19: =G19+H18 | I19: =H19+I18 | J19: =I19+J18 | ... AR19: =AQ19+AR18
A20: OSBL — infrastructure & civil — depreciation | B20: =IF(0<'Parameters'!$B$5,0,MAX(0,MIN(B19*$B$16*B4,B19-0))) | C20: =IF(1<'Parameters'!$B$5,0,MAX(0,MIN(C19*$B$16*C4,C19-B21))) | D20: =IF(2<'Parameters'!$B$5,0,MAX(0,MIN(D19*$B$16*D4,D19-C21))) | E20: =IF(3<'Parameters'!$B$5,0,MAX(0,MIN(E19*$B$16*E4,E19-D21))) | F20: =IF(4<'Parameters'!$B$5,0,MAX(0,MIN(F19*$B$16*F4,F19-E21))) | G20: =IF(5<'Parameters'!$B$5,0,MAX(0,MIN(G19*$B$16*G4,G19-F21))) | H20: =IF(6<'Parameters'!$B$5,0,MAX(0,MIN(H19*$B$16*H4,H19-G21))) | I20: =IF(7<'Parameters'!$B$5,0,MAX(0,MIN(I19*$B$16*I4,I19-H21))) | J20: =IF(8<'Parameters'!$B$5,0,MAX(0,MIN(J19*$B$16*J4,J19-I21))) | K20: =IF(9<'Parameters'!$B$5,0,MAX(0,MIN(K19*$B$16*K4,K19-J21))) | L20: =IF(10<'Parameters'!$B$5,0,MAX(0,MIN(L19*$B$16*L4,L19-K21))) | M20: =IF(11<'Parameters'!$B$5,0,MAX(0,MIN(M19*$B$16*M4,M19-L21))) | N20: =IF(12<'Parameters'!$B$5,0,MAX(0,MIN(N19*$B$16*N4,N19-M21))) | O20: =IF(13<'Parameters'!$B$5,0,MAX(0,MIN(O19*$B$16*O4,O19-N21))) | P20: =IF(14<'Parameters'!$B$5,0,MAX(0,MIN(P19*$B$16*P4,P19-O21))) | Q20: =IF(15<'Parameters'!$B$5,0,MAX(0,MIN(Q19*$B$16*Q4,Q19-P21))) | R20: =IF(16<'Parameters'!$B$5,0,MAX(0,MIN(R19*$B$16*R4,R19-Q21))) | S20: =IF(17<'Parameters'!$B$5,0,MAX(0,MIN(S19*$B$16*S4,S19-R21))) | T20: =IF(18<'Parameters'!$B$5,0,MAX(0,MIN(T19*$B$16*T4,T19-S21))) | U20: =IF(19<'Parameters'!$B$5,0,MAX(0,MIN(U19*$B$16*U4,U19-T21))) | V20: =IF(20<'Parameters'!$B$5,0,MAX(0,MIN(V19*$B$16*V4,V19-U21))) | W20: =IF(21<'Parameters'!$B$5,0,MAX(0,MIN(W19*$B$16*W4,W19-V21))) | X20: =IF(22<'Parameters'!$B$5,0,MAX(0,MIN(X19*$B$16*X4,X19-W21))) | Y20: =IF(23<'Parameters'!$B$5,0,MAX(0,MIN(Y19*$B$16*Y4,Y19-X21))) | Z20: =IF(24<'Parameters'!$B$5,0,MAX(0,MIN(Z19*$B$16*Z4,Z19-Y21))) | AA20: =IF(25<'Parameters'!$B$5,0,MAX(0,MIN(AA19*$B$16*AA4,AA19-Z21))) | AB20: =IF(26<'Parameters'!$B$5,0,MAX(0,MIN(AB19*$B$16*AB4,AB19-AA21))) | AC20: =IF(27<'Parameters'!$B$5,0,MAX(0,MIN(AC19*$B$16*AC4,AC19-AB21))) | AD20: =IF(28<'Parameters'!$B$5,0,MAX(0,MIN(AD19*$B$16*AD4,AD19-AC21))) | AE20: =IF(29<'Parameters'!$B$5,0,MAX(0,MIN(AE19*$B$16*AE4,AE19-AD21))) | AF20: =IF(30<'Parameters'!$B$5,0,MAX(0,MIN(AF19*$B$16*AF4,AF19-AE21))) | AG20: =IF(31<'Parameters'!$B$5,0,MAX(0,MIN(AG19*$B$16*AG4,AG19-AF21))) | AH20: =IF(32<'Parameters'!$B$5,0,MAX(0,MIN(AH19*$B$16*AH4,AH19-AG21))) | AI20: =IF(33<'Parameters'!$B$5,0,MAX(0,MIN(AI19*$B$16*AI4,AI19-AH21))) | AJ20: =IF(34<'Parameters'!$B$5,0,MAX(0,MIN(AJ19*$B$16*AJ4,AJ19-AI21))) | AK20: =IF(35<'Parameters'!$B$5,0,MAX(0,MIN(AK19*$B$16*AK4,AK19-AJ21))) | AL20: =IF(36<'Parameters'!$B$5,0,MAX(0,MIN(AL19*$B$16*AL4,AL19-AK21))) | AM20: =IF(37<'Parameters'!$B$5,0,MAX(0,MIN(AM19*$B$16*AM4,AM19-AL21))) | AN20: =IF(38<'Parameters'!$B$5,0,MAX(0,MIN(AN19*$B$16*AN4,AN19-AM21))) | AO20: =IF(39<'Parameters'!$B$5,0,MAX(0,MIN(AO19*$B$16*AO4,AO19-AN21))) | AP20: =IF(40<'Parameters'!$B$5,0,MAX(0,MIN(AP19*$B$16*AP4,AP19-AO21))) | AQ20: =IF(41<'Parameters'!$B$5,0,MAX(0,MIN(AQ19*$B$16*AQ4,AQ19-AP21))) | AR20: =IF(42<'Parameters'!$B$5,0,MAX(0,MIN(AR19*$B$16*AR4,AR19-AQ21)))
A21: OSBL — infrastructure & civil — accumulated depreciation | B21: =B20 | C21: =B21+C20 | D21: =C21+D20 | E21: =D21+E20 | F21: =E21+F20 | G21: =F21+G20 | H21: =G21+H20 | I21: =H21+I20 | J21: =I21+J20 | ... AR21: =AQ21+AR20
A23: Other — overheads & licensing — total cost | B23: 2582095
A24: Other — overheads & licensing — monthly depreciation rate | B24: 0.0083333333
A25: Other — overheads & licensing — phasing % | B25: 0.02 | C25: 0.03 | D25: 0.04 | E25: 0.05 | F25: 0.06 | G25: 0.07 | H25: 0.08 | I25: 0.08 | J25: 0.08 | K25: 0.08 | L25: 0.08 | M25: 0.07 | N25: 0.07 | O25: 0.06 | P25: 0.05 | Q25: 0.04 | R25: 0.03 | S25: 0.01 | T25: 0 | U25: 0 | V25: 0 | W25: 0 | X25: 0 | Y25: 0 | Z25: 0 | AA25: 0 | AB25: 0 | AC25: 0 | AD25: 0 | AE25: 0 | AF25: 0 | AG25: 0 | AH25: 0 | AI25: 0 | AJ25: 0 | AK25: 0 | AL25: 0 | AM25: 0 | AN25: 0 | AO25: 0 | AP25: 0 | AQ25: 0 | AR25: 0
A26: Other — overheads & licensing — spend | B26: =$B$23*B25 | C26: =$B$23*C25 | D26: =$B$23*D25 | E26: =$B$23*E25 | F26: =$B$23*F25 | G26: =$B$23*G25 | H26: =$B$23*H25 | I26: =$B$23*I25 | ... AR26: =$B$23*AR25
A27: Other — overheads & licensing — cumulative cost | B27: =B26 | C27: =B27+C26 | D27: =C27+D26 | E27: =D27+E26 | F27: =E27+F26 | G27: =F27+G26 | H27: =G27+H26 | I27: =H27+I26 | J27: =I27+J26 | ... AR27: =AQ27+AR26
A28: Other — overheads & licensing — depreciation | B28: =IF(0<'Parameters'!$B$5,0,MAX(0,MIN(B27*$B$24*B4,B27-0))) | C28: =IF(1<'Parameters'!$B$5,0,MAX(0,MIN(C27*$B$24*C4,C27-B29))) | D28: =IF(2<'Parameters'!$B$5,0,MAX(0,MIN(D27*$B$24*D4,D27-C29))) | E28: =IF(3<'Parameters'!$B$5,0,MAX(0,MIN(E27*$B$24*E4,E27-D29))) | F28: =IF(4<'Parameters'!$B$5,0,MAX(0,MIN(F27*$B$24*F4,F27-E29))) | G28: =IF(5<'Parameters'!$B$5,0,MAX(0,MIN(G27*$B$24*G4,G27-F29))) | H28: =IF(6<'Parameters'!$B$5,0,MAX(0,MIN(H27*$B$24*H4,H27-G29))) | I28: =IF(7<'Parameters'!$B$5,0,MAX(0,MIN(I27*$B$24*I4,I27-H29))) | J28: =IF(8<'Parameters'!$B$5,0,MAX(0,MIN(J27*$B$24*J4,J27-I29))) | K28: =IF(9<'Parameters'!$B$5,0,MAX(0,MIN(K27*$B$24*K4,K27-J29))) | L28: =IF(10<'Parameters'!$B$5,0,MAX(0,MIN(L27*$B$24*L4,L27-K29))) | M28: =IF(11<'Parameters'!$B$5,0,MAX(0,MIN(M27*$B$24*M4,M27-L29))) | N28: =IF(12<'Parameters'!$B$5,0,MAX(0,MIN(N27*$B$24*N4,N27-M29))) | O28: =IF(13<'Parameters'!$B$5,0,MAX(0,MIN(O27*$B$24*O4,O27-N29))) | P28: =IF(14<'Parameters'!$B$5,0,MAX(0,MIN(P27*$B$24*P4,P27-O29))) | Q28: =IF(15<'Parameters'!$B$5,0,MAX(0,MIN(Q27*$B$24*Q4,Q27-P29))) | R28: =IF(16<'Parameters'!$B$5,0,MAX(0,MIN(R27*$B$24*R4,R27-Q29))) | S28: =IF(17<'Parameters'!$B$5,0,MAX(0,MIN(S27*$B$24*S4,S27-R29))) | T28: =IF(18<'Parameters'!$B$5,0,MAX(0,MIN(T27*$B$24*T4,T27-S29))) | U28: =IF(19<'Parameters'!$B$5,0,MAX(0,MIN(U27*$B$24*U4,U27-T29))) | V28: =IF(20<'Parameters'!$B$5,0,MAX(0,MIN(V27*$B$24*V4,V27-U29))) | W28: =IF(21<'Parameters'!$B$5,0,MAX(0,MIN(W27*$B$24*W4,W27-V29))) | X28: =IF(22<'Parameters'!$B$5,0,MAX(0,MIN(X27*$B$24*X4,X27-W29))) | Y28: =IF(23<'Parameters'!$B$5,0,MAX(0,MIN(Y27*$B$24*Y4,Y27-X29))) | Z28: =IF(24<'Parameters'!$B$5,0,MAX(0,MIN(Z27*$B$24*Z4,Z27-Y29))) | AA28: =IF(25<'Parameters'!$B$5,0,MAX(0,MIN(AA27*$B$24*AA4,AA27-Z29))) | AB28: =IF(26<'Parameters'!$B$5,0,MAX(0,MIN(AB27*$B$24*AB4,AB27-AA29))) | AC28: =IF(27<'Parameters'!$B$5,0,MAX(0,MIN(AC27*$B$24*AC4,AC27-AB29))) | AD28: =IF(28<'Parameters'!$B$5,0,MAX(0,MIN(AD27*$B$24*AD4,AD27-AC29))) | AE28: =IF(29<'Parameters'!$B$5,0,MAX(0,MIN(AE27*$B$24*AE4,AE27-AD29))) | AF28: =IF(30<'Parameters'!$B$5,0,MAX(0,MIN(AF27*$B$24*AF4,AF27-AE29))) | AG28: =IF(31<'Parameters'!$B$5,0,MAX(0,MIN(AG27*$B$24*AG4,AG27-AF29))) | AH28: =IF(32<'Parameters'!$B$5,0,MAX(0,MIN(AH27*$B$24*AH4,AH27-AG29))) | AI28: =IF(33<'Parameters'!$B$5,0,MAX(0,MIN(AI27*$B$24*AI4,AI27-AH29))) | AJ28: =IF(34<'Parameters'!$B$5,0,MAX(0,MIN(AJ27*$B$24*AJ4,AJ27-AI29))) | AK28: =IF(35<'Parameters'!$B$5,0,MAX(0,MIN(AK27*$B$24*AK4,AK27-AJ29))) | AL28: =IF(36<'Parameters'!$B$5,0,MAX(0,MIN(AL27*$B$24*AL4,AL27-AK29))) | AM28: =IF(37<'Parameters'!$B$5,0,MAX(0,MIN(AM27*$B$24*AM4,AM27-AL29))) | AN28: =IF(38<'Parameters'!$B$5,0,MAX(0,MIN(AN27*$B$24*AN4,AN27-AM29))) | AO28: =IF(39<'Parameters'!$B$5,0,MAX(0,MIN(AO27*$B$24*AO4,AO27-AN29))) | AP28: =IF(40<'Parameters'!$B$5,0,MAX(0,MIN(AP27*$B$24*AP4,AP27-AO29))) | AQ28: =IF(41<'Parameters'!$B$5,0,MAX(0,MIN(AQ27*$B$24*AQ4,AQ27-AP29))) | AR28: =IF(42<'Parameters'!$B$5,0,MAX(0,MIN(AR27*$B$24*AR4,AR27-AQ29)))
A29: Other — overheads & licensing — accumulated depreciation | B29: =B28 | C29: =B29+C28 | D29: =C29+D28 | E29: =D29+E28 | F29: =E29+F28 | G29: =F29+G28 | H29: =G29+H28 | I29: =H29+I28 | J29: =I29+J28 | ... AR29: =AQ29+AR28
A31: Land / plot purchase — total cost | B31: 1375000
A32: Land / plot purchase — monthly depreciation rate | B32: 0
A33: Land / plot purchase — phasing % | B33: 1 | C33: 0 | D33: 0 | E33: 0 | F33: 0 | G33: 0 | H33: 0 | I33: 0 | J33: 0 | K33: 0 | L33: 0 | M33: 0 | N33: 0 | O33: 0 | P33: 0 | Q33: 0 | R33: 0 | S33: 0 | T33: 0 | U33: 0 | V33: 0 | W33: 0 | X33: 0 | Y33: 0 | Z33: 0 | AA33: 0 | AB33: 0 | AC33: 0 | AD33: 0 | AE33: 0 | AF33: 0 | AG33: 0 | AH33: 0 | AI33: 0 | AJ33: 0 | AK33: 0 | AL33: 0 | AM33: 0 | AN33: 0 | AO33: 0 | AP33: 0 | AQ33: 0 | AR33: 0
A34: Land / plot purchase — spend | B34: =$B$31*B33 | C34: =$B$31*C33 | D34: =$B$31*D33 | E34: =$B$31*E33 | F34: =$B$31*F33 | G34: =$B$31*G33 | H34: =$B$31*H33 | I34: =$B$31*I33 | ... AR34: =$B$31*AR33
A35: Land / plot purchase — cumulative cost | B35: =B34 | C35: =B35+C34 | D35: =C35+D34 | E35: =D35+E34 | F35: =E35+F34 | G35: =F35+G34 | H35: =G35+H34 | I35: =H35+I34 | J35: =I35+J34 | ... AR35: =AQ35+AR34
A36: Land / plot purchase — depreciation | B36: =IF(0<'Parameters'!$B$5,0,MAX(0,MIN(B35*$B$32*B4,B35-0))) | C36: =IF(1<'Parameters'!$B$5,0,MAX(0,MIN(C35*$B$32*C4,C35-B37))) | D36: =IF(2<'Parameters'!$B$5,0,MAX(0,MIN(D35*$B$32*D4,D35-C37))) | E36: =IF(3<'Parameters'!$B$5,0,MAX(0,MIN(E35*$B$32*E4,E35-D37))) | F36: =IF(4<'Parameters'!$B$5,0,MAX(0,MIN(F35*$B$32*F4,F35-E37))) | G36: =IF(5<'Parameters'!$B$5,0,MAX(0,MIN(G35*$B$32*G4,G35-F37))) | H36: =IF(6<'Parameters'!$B$5,0,MAX(0,MIN(H35*$B$32*H4,H35-G37))) | I36: =IF(7<'Parameters'!$B$5,0,MAX(0,MIN(I35*$B$32*I4,I35-H37))) | J36: =IF(8<'Parameters'!$B$5,0,MAX(0,MIN(J35*$B$32*J4,J35-I37))) | K36: =IF(9<'Parameters'!$B$5,0,MAX(0,MIN(K35*$B$32*K4,K35-J37))) | L36: =IF(10<'Parameters'!$B$5,0,MAX(0,MIN(L35*$B$32*L4,L35-K37))) | M36: =IF(11<'Parameters'!$B$5,0,MAX(0,MIN(M35*$B$32*M4,M35-L37))) | N36: =IF(12<'Parameters'!$B$5,0,MAX(0,MIN(N35*$B$32*N4,N35-M37))) | O36: =IF(13<'Parameters'!$B$5,0,MAX(0,MIN(O35*$B$32*O4,O35-N37))) | P36: =IF(14<'Parameters'!$B$5,0,MAX(0,MIN(P35*$B$32*P4,P35-O37))) | Q36: =IF(15<'Parameters'!$B$5,0,MAX(0,MIN(Q35*$B$32*Q4,Q35-P37))) | R36: =IF(16<'Parameters'!$B$5,0,MAX(0,MIN(R35*$B$32*R4,R35-Q37))) | S36: =IF(17<'Parameters'!$B$5,0,MAX(0,MIN(S35*$B$32*S4,S35-R37))) | T36: =IF(18<'Parameters'!$B$5,0,MAX(0,MIN(T35*$B$32*T4,T35-S37))) | U36: =IF(19<'Parameters'!$B$5,0,MAX(0,MIN(U35*$B$32*U4,U35-T37))) | V36: =IF(20<'Parameters'!$B$5,0,MAX(0,MIN(V35*$B$32*V4,V35-U37))) | W36: =IF(21<'Parameters'!$B$5,0,MAX(0,MIN(W35*$B$32*W4,W35-V37))) | X36: =IF(22<'Parameters'!$B$5,0,MAX(0,MIN(X35*$B$32*X4,X35-W37))) | Y36: =IF(23<'Parameters'!$B$5,0,MAX(0,MIN(Y35*$B$32*Y4,Y35-X37))) | Z36: =IF(24<'Parameters'!$B$5,0,MAX(0,MIN(Z35*$B$32*Z4,Z35-Y37))) | AA36: =IF(25<'Parameters'!$B$5,0,MAX(0,MIN(AA35*$B$32*AA4,AA35-Z37))) | AB36: =IF(26<'Parameters'!$B$5,0,MAX(0,MIN(AB35*$B$32*AB4,AB35-AA37))) | AC36: =IF(27<'Parameters'!$B$5,0,MAX(0,MIN(AC35*$B$32*AC4,AC35-AB37))) | AD36: =IF(28<'Parameters'!$B$5,0,MAX(0,MIN(AD35*$B$32*AD4,AD35-AC37))) | AE36: =IF(29<'Parameters'!$B$5,0,MAX(0,MIN(AE35*$B$32*AE4,AE35-AD37))) | AF36: =IF(30<'Parameters'!$B$5,0,MAX(0,MIN(AF35*$B$32*AF4,AF35-AE37))) | AG36: =IF(31<'Parameters'!$B$5,0,MAX(0,MIN(AG35*$B$32*AG4,AG35-AF37))) | AH36: =IF(32<'Parameters'!$B$5,0,MAX(0,MIN(AH35*$B$32*AH4,AH35-AG37))) | AI36: =IF(33<'Parameters'!$B$5,0,MAX(0,MIN(AI35*$B$32*AI4,AI35-AH37))) | AJ36: =IF(34<'Parameters'!$B$5,0,MAX(0,MIN(AJ35*$B$32*AJ4,AJ35-AI37))) | AK36: =IF(35<'Parameters'!$B$5,0,MAX(0,MIN(AK35*$B$32*AK4,AK35-AJ37))) | AL36: =IF(36<'Parameters'!$B$5,0,MAX(0,MIN(AL35*$B$32*AL4,AL35-AK37))) | AM36: =IF(37<'Parameters'!$B$5,0,MAX(0,MIN(AM35*$B$32*AM4,AM35-AL37))) | AN36: =IF(38<'Parameters'!$B$5,0,MAX(0,MIN(AN35*$B$32*AN4,AN35-AM37))) | AO36: =IF(39<'Parameters'!$B$5,0,MAX(0,MIN(AO35*$B$32*AO4,AO35-AN37))) | AP36: =IF(40<'Parameters'!$B$5,0,MAX(0,MIN(AP35*$B$32*AP4,AP35-AO37))) | AQ36: =IF(41<'Parameters'!$B$5,0,MAX(0,MIN(AQ35*$B$32*AQ4,AQ35-AP37))) | AR36: =IF(42<'Parameters'!$B$5,0,MAX(0,MIN(AR35*$B$32*AR4,AR35-AQ37)))
A37: Land / plot purchase — accumulated depreciation | B37: =B36 | C37: =B37+C36 | D37: =C37+D36 | E37: =D37+E36 | F37: =E37+F36 | G37: =F37+G36 | H37: =G37+H36 | I37: =H37+I36 | J37: =I37+J36 | ... AR37: =AQ37+AR36
A39: Total CAPEX spend | B39: =B10+B18+B26+B34 | C39: =C10+C18+C26+C34 | D39: =D10+D18+D26+D34 | E39: =E10+E18+E26+E34 | F39: =F10+F18+F26+F34 | G39: =G10+G18+G26+G34 | H39: =H10+H18+H26+H34 | I39: =I10+I18+I26+I34 | ... AR39: =AR10+AR18+AR26+AR34
A40: Cumulative deployed CAPEX | B40: =B39 | C40: =B40+C39 | D40: =C40+D39 | E40: =D40+E39 | F40: =E40+F39 | G40: =F40+G39 | H40: =G40+H39 | I40: =H40+I39 | J40: =I40+J39 | ... AR40: =AQ40+AR39
A41: Total depreciation | B41: =B12+B20+B28+B36 | C41: =C12+C20+C28+C36 | D41: =D12+D20+D28+D36 | E41: =E12+E20+E28+E36 | F41: =F12+F20+F28+F36 | G41: =G12+G20+G28+G36 | H41: =H12+H20+H28+H36 | I41: =I12+I20+I28+I36 | ... AR41: =AR12+AR20+AR28+AR36

Sheet UnitEcon
A1: Unit economics — revenue and COGS drivers
A3: Driver — by plan year | B3: Y1 | C3: Y2 | D3: Y3 | E3: Y4 | F3: Y5 | G3: Y6 | H3: Y7 | I3: Y8 | J3: Y9 | K3: Y10
A4: Price per ton MGO (EUR) | B4: 688.8469 | C4: 688.8469 | D4: 688.8469 | E4: 688.8469 | F4: 688.8469 | G4: 688.8469 | H4: 688.8469 | I4: 688.8469 | J4: 688.8469 | K4: 688.8469
A5: Annual operating hours at 100% | B5: 8000 | C5: 8000 | D5: 8000 | E5: 8000 | F5: 8000 | G5: 8000 | H5: 8000 | I5: 8000 | J5: 8000 | K5: 8000
A6: MGO yield (kg/h) | B6: 1840 | C6: 1840 | D6: 1840 | E6: 1840 | F6: 1840 | G6: 1840 | H6: 1840 | I6: 1840 | J6: 1840 | K6: 1840
A7: MTS input (kg/h) | B7: 2000 | C7: 2000 | D7: 2000 | E7: 2000 | F7: 2000 | G7: 2000 | H7: 2000 | I7: 2000 | J7: 2000 | K7: 2000
A8: Reactant input (kg/h) | B8: 50 | C8: 50 | D8: 50 | E8: 50 | F8: 50 | G8: 50 | H8: 50 | I8: 50 | J8: 50 | K8: 50
A9: Residue yield (kg/h) | B9: 210 | C9: 210 | D9: 210 | E9: 210 | F9: 210 | G9: 210 | H9: 210 | I9: 210 | J9: 210 | K9: 210
A10: Water yield (kg/h) | B10: 0 | C10: 0 | D10: 0 | E10: 0 | F10: 0 | G10: 0 | H10: 0 | I10: 0 | J10: 0 | K10: 0
A11: MTS cost per ton | B11: 180.2806 | C11: 180.2806 | D11: 180.2806 | E11: 180.2806 | F11: 180.2806 | G11: 180.2806 | H11: 180.2806 | I11: 180.2806 | J11: 180.2806 | K11: 180.2806
A12: Reactant cost per ton | B12: 3670 | C12: 3670 | D12: 3670 | E12: 3670 | F12: 3670 | G12: 3670 | H12: 3670 | I12: 3670 | J12: 3670 | K12: 3670
A13: Residue cost per ton | B13: 360 | C13: 360 | D13: 360 | E13: 360 | F13: 360 | G13: 360 | H13: 360 | I13: 360 | J13: 360 | K13: 360
A14: Water cost per ton | B14: 0 | C14: 0 | D14: 0 | E14: 0 | F14: 0 | G14: 0 | H14: 0 | I14: 0 | J14: 0 | K14: 0
A15: Electricity price per kWh | B15: 0.1088692 | C15: 0.1088692 | D15: 0.1088692 | E15: 0.1088692 | F15: 0.1088692 | G15: 0.1088692 | H15: 0.1088692 | I15: 0.1088692 | J15: 0.1088692 | K15: 0.1088692
... A19: Maintenance % p.a. of deployed CAPEX | B19: 0.04 | C19: 0.04 | D19: 0.04 | E19: 0.04 | F19: 0.04 | G19: 0.04 | H19: 0.04 | I19: 0.04 | J19: 0.04 | K19: 0.04
A21: Driver — expanded to periods | B21: Jan-27 | C21: Feb-27 | D21: Mar-27 | E21: Apr-27 | F21: May-27 | G21: Jun-27 | H21: Jul-27 | I21: Aug-27 | J21: Sep-27 | K21: Oct-27 | L21: Nov-27 | M21: Dec-27 | N21: Jan-28 | O21: Feb-28 | P21: Mar-28 | Q21: Apr-28 | R21: May-28 | S21: Jun-28 | T21: Jul-28 | U21: Aug-28 | V21: Sep-28 | W21: Oct-28 | X21: Nov-28 | Y21: Dec-28 | Z21: Jan-29 | AA21: Feb-29 | AB21: Mar-29 | AC21: Apr-29 | AD21: May-29 | AE21: Jun-29 | AF21: Jul-29 | AG21: Aug-29 | AH21: Sep-29 | AI21: Oct-29 | AJ21: Nov-29 | AK21: Dec-29 | AL21: Y4 | AM21: Y5 | AN21: Y6 | AO21: Y7 | AP21: Y8 | AQ21: Y9 | AR21: Y10
A22: Price per ton MGO (EUR) | B22: =INDEX($B$4:$K$4,1,'CAPEX'!B5) | C22: =INDEX($B$4:$K$4,1,'CAPEX'!C5) | D22: =INDEX($B$4:$K$4,1,'CAPEX'!D5) | E22: =INDEX($B$4:$K$4,1,'CAPEX'!E5) | F22: =INDEX($B$4:$K$4,1,'CAPEX'!F5) | G22: =INDEX($B$4:$K$4,1,'CAPEX'!G5) | H22: =INDEX($B$4:$K$4,1,'CAPEX'!H5) | I22: =INDEX($B$4:$K$4,1,'CAPEX'!I5) | ... AR22: =INDEX($B$4:$K$4,1,'CAPEX'!AR5)
A23: Annual operating hours at 100% | B23: =INDEX($B$5:$K$5,1,'CAPEX'!B5) | C23: =INDEX($B$5:$K$5,1,'CAPEX'!C5) | D23: =INDEX($B$5:$K$5,1,'CAPEX'!D5) | E23: =INDEX($B$5:$K$5,1,'CAPEX'!E5) | F23: =INDEX($B$5:$K$5,1,'CAPEX'!F5) | G23: =INDEX($B$5:$K$5,1,'CAPEX'!G5) | H23: =INDEX($B$5:$K$5,1,'CAPEX'!H5) | I23: =INDEX($B$5:$K$5,1,'CAPEX'!I5) | ... AR23: =INDEX($B$5:$K$5,1,'CAPEX'!AR5)
A24: MGO yield (kg/h) | B24: =INDEX($B$6:$K$6,1,'CAPEX'!B5) | C24: =INDEX($B$6:$K$6,1,'CAPEX'!C5) | D24: =INDEX($B$6:$K$6,1,'CAPEX'!D5) | E24: =INDEX($B$6:$K$6,1,'CAPEX'!E5) | F24: =INDEX($B$6:$K$6,1,'CAPEX'!F5) | G24: =INDEX($B$6:$K$6,1,'CAPEX'!G5) | H24: =INDEX($B$6:$K$6,1,'CAPEX'!H5) | I24: =INDEX($B$6:$K$6,1,'CAPEX'!I5) | ... AR24: =INDEX($B$6:$K$6,1,'CAPEX'!AR5)
A25: MTS input (kg/h) | B25: =INDEX($B$7:$K$7,1,'CAPEX'!B5) | C25: =INDEX($B$7:$K$7,1,'CAPEX'!C5) | D25: =INDEX($B$7:$K$7,1,'CAPEX'!D5) | E25: =INDEX($B$7:$K$7,1,'CAPEX'!E5) | F25: =INDEX($B$7:$K$7,1,'CAPEX'!F5) | G25: =INDEX($B$7:$K$7,1,'CAPEX'!G5) | H25: =INDEX($B$7:$K$7,1,'CAPEX'!H5) | I25: =INDEX($B$7:$K$7,1,'CAPEX'!I5) | ... AR25: =INDEX($B$7:$K$7,1,'CAPEX'!AR5)
A26: Reactant input (kg/h) | B26: =INDEX($B$8:$K$8,1,'CAPEX'!B5) | C26: =INDEX($B$8:$K$8,1,'CAPEX'!C5) | D26: =INDEX($B$8:$K$8,1,'CAPEX'!D5) | E26: =INDEX($B$8:$K$8,1,'CAPEX'!E5) | F26: =INDEX($B$8:$K$8,1,'CAPEX'!F5) | G26: =INDEX($B$8:$K$8,1,'CAPEX'!G5) | H26: =INDEX($B$8:$K$8,1,'CAPEX'!H5) | I26: =INDEX($B$8:$K$8,1,'CAPEX'!I5) | ... AR26: =INDEX($B$8:$K$8,1,'CAPEX'!AR5)
A27: Residue yield (kg/h) | B27: =INDEX($B$9:$K$9,1,'CAPEX'!B5) | C27: =INDEX($B$9:$K$9,1,'CAPEX'!C5) | D27: =INDEX($B$9:$K$9,1,'CAPEX'!D5) | E27: =INDEX($B$9:$K$9,1,'CAPEX'!E5) | F27: =INDEX($B$9:$K$9,1,'CAPEX'!F5) | G27: =INDEX($B$9:$K$9,1,'CAPEX'!G5) | H27: =INDEX($B$9:$K$9,1,'CAPEX'!H5) | I27: =INDEX($B$9:$K$9,1,'CAPEX'!I5) | ... AR27: =INDEX($B$9:$K$9,1,'CAPEX'!AR5)
A28: Water yield (kg/h) | B28: =INDEX($B$10:$K$10,1,'CAPEX'!B5) | C28: =INDEX($B$10:$K$10,1,'CAPEX'!C5) | D28: =INDEX($B$10:$K$10,1,'CAPEX'!D5) | E28: =INDEX($B$10:$K$10,1,'CAPEX'!E5) | F28: =INDEX($B$10:$K$10,1,'CAPEX'!F5) | G28: =INDEX($B$10:$K$10,1,'CAPEX'!G5) | H28: =INDEX($B$10:$K$10,1,'CAPEX'!H5) | I28: =INDEX($B$10:$K$10,1,'CAPEX'!I5) | ... AR28: =INDEX($B$10:$K$10,1,'CAPEX'!AR5)
A29: MTS cost per ton | B29: =INDEX($B$11:$K$11,1,'CAPEX'!B5) | C29: =INDEX($B$11:$K$11,1,'CAPEX'!C5) | D29: =INDEX($B$11:$K$11,1,'CAPEX'!D5) | E29: =INDEX($B$11:$K$11,1,'CAPEX'!E5) | F29: =INDEX($B$11:$K$11,1,'CAPEX'!F5) | G29: =INDEX($B$11:$K$11,1,'CAPEX'!G5) | H29: =INDEX($B$11:$K$11,1,'CAPEX'!H5) | I29: =INDEX($B$11:$K$11,1,'CAPEX'!I5) | ... AR29: =INDEX($B$11:$K$11,1,'CAPEX'!AR5)
A30: Reactant cost per ton | B30: =INDEX($B$12:$K$12,1,'CAPEX'!B5) | C30: =INDEX($B$12:$K$12,1,'CAPEX'!C5) | D30: =INDEX($B$12:$K$12,1,'CAPEX'!D5) | E30: =INDEX($B$12:$K$12,1,'CAPEX'!E5) | F30: =INDEX($B$12:$K$12,1,'CAPEX'!F5) | G30: =INDEX($B$12:$K$12,1,'CAPEX'!G5) | H30: =INDEX($B$12:$K$12,1,'CAPEX'!H5) | I30: =INDEX($B$12:$K$12,1,'CAPEX'!I5) | ... AR30: =INDEX($B$12:$K$12,1,'CAPEX'!AR5)
A31: Residue cost per ton | B31: =INDEX($B$13:$K$13,1,'CAPEX'!B5) | C31: =INDEX($B$13:$K$13,1,'CAPEX'!C5) | D31: =INDEX($B$13:$K$13,1,'CAPEX'!D5) | E31: =INDEX($B$13:$K$13,1,'CAPEX'!E5) | F31: =INDEX($B$13:$K$13,1,'CAPEX'!F5) | G31: =INDEX($B$13:$K$13,1,'CAPEX'!G5) | H31: =INDEX($B$13:$K$13,1,'CAPEX'!H5) | I31: =INDEX($B$13:$K$13,1,'CAPEX'!I5) | ... AR31: =INDEX($B$13:$K$13,1,'CAPEX'!AR5)
A32: Water cost per ton | B32: =INDEX($B$14:$K$14,1,'CAPEX'!B5) | C32: =INDEX($B$14:$K$14,1,'CAPEX'!C5) | D32: =INDEX($B$14:$K$14,1,'CAPEX'!D5) | E32: =INDEX($B$14:$K$14,1,'CAPEX'!E5) | F32: =INDEX($B$14:$K$14,1,'CAPEX'!F5) | G32: =INDEX($B$14:$K$14,1,'CAPEX'!G5) | H32: =INDEX($B$14:$K$14,1,'CAPEX'!H5) | I32: =INDEX($B$14:$K$14,1,'CAPEX'!I5) | ... AR32: =INDEX($B$14:$K$14,1,'CAPEX'!AR5)
A33: Electricity price per kWh | B33: =INDEX($B$15:$K$15,1,'CAPEX'!B5) | C33: =INDEX($B$15:$K$15,1,'CAPEX'!C5) | D33: =INDEX($B$15:$K$15,1,'CAPEX'!D5) | E33: =INDEX($B$15:$K$15,1,'CAPEX'!E5) | F33: =INDEX($B$15:$K$15,1,'CAPEX'!F5) | G33: =INDEX($B$15:$K$15,1,'CAPEX'!G5) | H33: =INDEX($B$15:$K$15,1,'CAPEX'!H5) | I33: =INDEX($B$15:$K$15,1,'CAPEX'!I5) | ... AR33: =INDEX($B$15:$K$15,1,'CAPEX'!AR5)
A34: Electricity consumption (kWh/h) | B34: =INDEX($B$16:$K$16,1,'CAPEX'!B5) | C34: =INDEX($B$16:$K$16,1,'CAPEX'!C5) | D34: =INDEX($B$16:$K$16,1,'CAPEX'!D5) | E34: =INDEX($B$16:$K$16,1,'CAPEX'!E5) | F34: =INDEX($B$16:$K$16,1,'CAPEX'!F5) | G34: =INDEX($B$16:$K$16,1,'CAPEX'!G5) | H34: =INDEX($B$16:$K$16,1,'CAPEX'!H5) | I34: =INDEX($B$16:$K$16,1,'CAPEX'!I5) | ... AR34: =INDEX($B$16:$K$16,1,'CAPEX'!AR5)
A35: Heat price per kWh | B35: =INDEX($B$17:$K$17,1,'CAPEX'!B5) | C35: =INDEX($B$17:$K$17,1,'CAPEX'!C5) | D35: =INDEX($B$17:$K$17,1,'CAPEX'!D5) | E35: =INDEX($B$17:$K$17,1,'CAPEX'!E5) | F35: =INDEX($B$17:$K$17,1,'CAPEX'!F5) | G35: =INDEX($B$17:$K$17,1,'CAPEX'!G5) | H35: =INDEX($B$17:$K$17,1,'CAPEX'!H5) | I35: =INDEX($B$17:$K$17,1,'CAPEX'!I5) | ... AR35: =INDEX($B$17:$K$17,1,'CAPEX'!AR5)
A36: Heat consumption (kWh/h) | B36: =INDEX($B$18:$K$18,1,'CAPEX'!B5) | C36: =INDEX($B$18:$K$18,1,'CAPEX'!C5) | D36: =INDEX($B$18:$K$18,1,'CAPEX'!D5) | E36: =INDEX($B$18:$K$18,1,'CAPEX'!E5) | F36: =INDEX($B$18:$K$18,1,'CAPEX'!F5) | G36: =INDEX($B$18:$K$18,1,'CAPEX'!G5) | H36: =INDEX($B$18:$K$18,1,'CAPEX'!H5) | I36: =INDEX($B$18:$K$18,1,'CAPEX'!I5) | ... AR36: =INDEX($B$18:$K$18,1,'CAPEX'!AR5)
A37: Maintenance % p.a. of deployed CAPEX | B37: =INDEX($B$19:$K$19,1,'CAPEX'!B5) | C37: =INDEX($B$19:$K$19,1,'CAPEX'!C5) | D37: =INDEX($B$19:$K$19,1,'CAPEX'!D5) | E37: =INDEX($B$19:$K$19,1,'CAPEX'!E5) | F37: =INDEX($B$19:$K$19,1,'CAPEX'!F5) | G37: =INDEX($B$19:$K$19,1,'CAPEX'!G5) | H37: =INDEX($B$19:$K$19,1,'CAPEX'!H5) | I37: =INDEX($B$19:$K$19,1,'CAPEX'!I5) | ... AR37: =INDEX($B$19:$K$19,1,'CAPEX'!AR5)
A38: Nameplate capacity (t/y) | B38: ='UnitEcon'!B24*'UnitEcon'!B23/1000 | C38: ='UnitEcon'!C24*'UnitEcon'!C23/1000 | D38: ='UnitEcon'!D24*'UnitEcon'!D23/1000 | E38: ='UnitEcon'!E24*'UnitEcon'!E23/1000 | F38: ='UnitEcon'!F24*'UnitEcon'!F23/1000 | G38: ='UnitEcon'!G24*'UnitEcon'!G23/1000 | H38: ='UnitEcon'!H24*'UnitEcon'!H23/1000 | I38: ='UnitEcon'!I24*'UnitEcon'!I23/1000 | ... AR38: ='UnitEcon'!AR24*'UnitEcon'!AR23/1000
A40: Volume | B40: Jan-27 | C40: Feb-27 | D40: Mar-27 | E40: Apr-27 | F40: May-27 | G40: Jun-27 | H40: Jul-27 | I40: Aug-27 | J40: Sep-27 | K40: Oct-27 | L40: Nov-27 | M40: Dec-27 | N40: Jan-28 | O40: Feb-28 | P40: Mar-28 | Q40: Apr-28 | R40: May-28 | S40: Jun-28 | T40: Jul-28 | U40: Aug-28 | V40: Sep-28 | W40: Oct-28 | X40: Nov-28 | Y40: Dec-28 | Z40: Jan-29 | AA40: Feb-29 | AB40: Mar-29 | AC40: Apr-29 | AD40: May-29 | AE40: Jun-29 | AF40: Jul-29 | AG40: Aug-29 | AH40: Sep-29 | AI40: Oct-29 | AJ40: Nov-29 | AK40: Dec-29 | AL40: Y4 | AM40: Y5 | AN40: Y6 | AO40: Y7 | AP40: Y8 | AQ40: Y9 | AR40: Y10
A41: Capacity utilisation % | B41: 0 | C41: 0 | D41: 0 | E41: 0 | F41: 0 | G41: 0 | H41: 0 | I41: 0 | J41: 0 | K41: 0 | L41: 0 | M41: 0 | N41: 0 | O41: 0 | P41: 0 | Q41: 0 | R41: 0 | S41: 0 | T41: 0.3 | U41: 0.45 | V41: 0.6 | W41: 0.7 | X41: 0.8 | Y41: 0.85 | Z41: 0.88 | AA41: 0.9 | AB41: 0.9 | AC41: 0.9 | AD41: 0.9 | AE41: 0.9 | AF41: 0.9 | AG41: 0.9 | AH41: 0.9 | AI41: 0.9 | AJ41: 0.9 | AK41: 0.9 | AL41: 0.9 | AM41: 0.9 | AN41: 0.9 | AO41: 0.9 | AP41: 0.9 | AQ41: 0.9 | AR41: 0.9
A42: Operating hours | B42: ='UnitEcon'!B23/12*'CAPEX'!B4*B41 | C42: ='UnitEcon'!C23/12*'CAPEX'!C4*C41 | D42: ='UnitEcon'!D23/12*'CAPEX'!D4*D41 | E42: ='UnitEcon'!E23/12*'CAPEX'!E4*E41 | F42: ='UnitEcon'!F23/12*'CAPEX'!F4*F41 | G42: ='UnitEcon'!G23/12*'CAPEX'!G4*G41 | H42: ='UnitEcon'!H23/12*'CAPEX'!H4*H41 | I42: ='UnitEcon'!I23/12*'CAPEX'!I4*I41 | ... AR42: ='UnitEcon'!AR23/12*'CAPEX'!AR4*AR41
A43: Tons produced | B43: ='UnitEcon'!B38/12*'CAPEX'!B4*B41 | C43: ='UnitEcon'!C38/12*'CAPEX'!C4*C41 | D43: ='UnitEcon'!D38/12*'CAPEX'!D4*D41 | E43: ='UnitEcon'!E38/12*'CAPEX'!E4*E41 | F43: ='UnitEcon'!F38/12*'CAPEX'!F4*F41 | G43: ='UnitEcon'!G38/12*'CAPEX'!G4*G41 | H43: ='UnitEcon'!H38/12*'CAPEX'!H4*H41 | I43: ='UnitEcon'!I38/12*'CAPEX'!I4*I41 | ... AR43: ='UnitEcon'!AR38/12*'CAPEX'!AR4*AR41

Sheet OPEX
A1: OPEX — personnel and other categories
A3: Line | B3: Jan-27 | C3: Feb-27 | D3: Mar-27 | E3: Apr-27 | F3: May-27 | G3: Jun-27 | H3: Jul-27 | I3: Aug-27 | J3: Sep-27 | K3: Oct-27 | L3: Nov-27 | M3: Dec-27 | N3: Jan-28 | O3: Feb-28 | P3: Mar-28 | Q3: Apr-28 | R3: May-28 | S3: Jun-28 | T3: Jul-28 | U3: Aug-28 | V3: Sep-28 | W3: Oct-28 | X3: Nov-28 | Y3: Dec-28 | Z3: Jan-29 | AA3: Feb-29 | AB3: Mar-29 | AC3: Apr-29 | AD3: May-29 | AE3: Jun-29 | AF3: Jul-29 | AG3: Aug-29 | AH3: Sep-29 | AI3: Oct-29 | AJ3: Nov-29 | AK3: Dec-29 | AL3: Y4 | AM3: Y5 | AN3: Y6 | AO3: Y7 | AP3: Y8 | AQ3: Y9 | AR3: Y10
A4: Compensation escalation factor | B4: =POWER(1+'Parameters'!$B$14,'CAPEX'!B5-1) | C4: =POWER(1+'Parameters'!$B$14,'CAPEX'!C5-1) | D4: =POWER(1+'Parameters'!$B$14,'CAPEX'!D5-1) | E4: =POWER(1+'Parameters'!$B$14,'CAPEX'!E5-1) | F4: =POWER(1+'Parameters'!$B$14,'CAPEX'!F5-1) | G4: =POWER(1+'Parameters'!$B$14,'CAPEX'!G5-1) | H4: =POWER(1+'Parameters'!$B$14,'CAPEX'!H5-1) | I4: =POWER(1+'Parameters'!$B$14,'CAPEX'!I5-1) | ... AR4: =POWER(1+'Parameters'!$B$14,'CAPEX'!AR5-1)
A5: OPEX escalation factor | B5: =POWER(1+'Parameters'!$B$13,'CAPEX'!B5-1) | C5: =POWER(1+'Parameters'!$B$13,'CAPEX'!C5-1) | D5: =POWER(1+'Parameters'!$B$13,'CAPEX'!D5-1) | E5: =POWER(1+'Parameters'!$B$13,'CAPEX'!E5-1) | F5: =POWER(1+'Parameters'!$B$13,'CAPEX'!F5-1) | G5: =POWER(1+'Parameters'!$B$13,'CAPEX'!G5-1) | H5: =POWER(1+'Parameters'!$B$13,'CAPEX'!H5-1) | I5: =POWER(1+'Parameters'!$B$13,'CAPEX'!I5-1) | ... AR5: =POWER(1+'Parameters'!$B$13,'CAPEX'!AR5-1)
A7: General manager — annual cost per FTE | B7: 126000
A8: General manager — FTEs | B8: 0 | C8: 0 | D8: 0 | E8: 0 | F8: 0 | G8: 0 | H8: 0 | I8: 0 | J8: 0 | K8: 0 | L8: 0 | M8: 0 | N8: 0 | O8: 0 | P8: 0 | Q8: 0.5 | R8: 0.5 | S8: 0.5 | T8: 1 | U8: 1 | V8: 1 | W8: 1 | X8: 1 | Y8: 1 | Z8: 1 | AA8: 1 | AB8: 1 | AC8: 1 | AD8: 1 | AE8: 1 | AF8: 1 | AG8: 1 | AH8: 1 | AI8: 1 | AJ8: 1 | AK8: 1 | AL8: 1 | AM8: 1 | AN8: 1 | AO8: 1 | AP8: 1 | AQ8: 1 | AR8: 1
A9: General manager — cost | B9: =$B$7*B4*B8*'CAPEX'!B4/12 | C9: =$B$7*C4*C8*'CAPEX'!C4/12 | D9: =$B$7*D4*D8*'CAPEX'!D4/12 | E9: =$B$7*E4*E8*'CAPEX'!E4/12 | F9: =$B$7*F4*F8*'CAPEX'!F4/12 | G9: =$B$7*G4*G8*'CAPEX'!G4/12 | H9: =$B$7*H4*H8*'CAPEX'!H4/12 | I9: =$B$7*I4*I8*'CAPEX'!I4/12 | ... AR9: =$B$7*AR4*AR8*'CAPEX'!AR4/12
A10: QA & HR supervisor — annual cost per FTE | B10: 73450
A11: QA & HR supervisor — FTEs | B11: 0 | C11: 0 | D11: 0 | E11: 0 | F11: 0 | G11: 0 | H11: 0 | I11: 0 | J11: 0 | K11: 0 | L11: 0 | M11: 0 | N11: 0 | O11: 0 | P11: 0 | Q11: 0.5 | R11: 0.5 | S11: 0.5 | T11: 1 | U11: 1 | V11: 1 | W11: 1 | X11: 1 | Y11: 1 | Z11: 1 | AA11: 1 | AB11: 1 | AC11: 1 | AD11: 1 | AE11: 1 | AF11: 1 | AG11: 1 | AH11: 1 | AI11: 1 | AJ11: 1 | AK11: 1 | AL11: 1 | AM11: 1 | AN11: 1 | AO11: 1 | AP11: 1 | AQ11: 1 | AR11: 1
A12: QA & HR supervisor — cost | B12: =$B$10*B4*B11*'CAPEX'!B4/12 | C12: =$B$10*C4*C11*'CAPEX'!C4/12 | D12: =$B$10*D4*D11*'CAPEX'!D4/12 | E12: =$B$10*E4*E11*'CAPEX'!E4/12 | F12: =$B$10*F4*F11*'CAPEX'!F4/12 | G12: =$B$10*G4*G11*'CAPEX'!G4/12 | H12: =$B$10*H4*H11*'CAPEX'!H4/12 | I12: =$B$10*I4*I11*'CAPEX'!I4/12 | ... AR12: =$B$10*AR4*AR11*'CAPEX'!AR4/12
A13: Process engineer supervisor — annual cost per FTE | B13: 73450
A14: Process engineer supervisor — FTEs | B14: 0 | C14: 0 | D14: 0 | E14: 0 | F14: 0 | G14: 0 | H14: 0 | I14: 0 | J14: 0 | K14: 0 | L14: 0 | M14: 0 | N14: 0 | O14: 0 | P14: 0 | Q14: 0.5 | R14: 0.5 | S14: 0.5 | T14: 1 | U14: 1 | V14: 1 | W14: 1 | X14: 1 | Y14: 1 | Z14: 1 | AA14: 1 | AB14: 1 | AC14: 1 | AD14: 1 | AE14: 1 | AF14: 1 | AG14: 1 | AH14: 1 | AI14: 1 | AJ14: 1 | AK14: 1 | AL14: 1 | AM14: 1 | AN14: 1 | AO14: 1 | AP14: 1 | AQ14: 1 | AR14: 1
A15: Process engineer supervisor — cost | B15: =$B$13*B4*B14*'CAPEX'!B4/12 | C15: =$B$13*C4*C14*'CAPEX'!C4/12 | D15: =$B$13*D4*D14*'CAPEX'!D4/12 | E15: =$B$13*E4*E14*'CAPEX'!E4/12 | F15: =$B$13*F4*F14*'CAPEX'!F4/12 | G15: =$B$13*G4*G14*'CAPEX'!G4/12 | H15: =$B$13*H4*H14*'CAPEX'!H4/12 | I15: =$B$13*I4*I14*'CAPEX'!I4/12 | ... AR15: =$B$13*AR4*AR14*'CAPEX'!AR4/12
A16: Process technician — annual cost per FTE | B16: 56500
A17: Process technician — FTEs | B17: 0 | C17: 0 | D17: 0 | E17: 0 | F17: 0 | G17: 0 | H17: 0 | I17: 0 | J17: 0 | K17: 0 | L17: 0 | M17: 0 | N17: 0 | O17: 0 | P17: 0 | Q17: 1.95 | R17: 1.95 | S17: 1.95 | T17: 3.9 | U17: 3.9 | V17: 3.9 | W17: 3.9 | X17: 3.9 | Y17: 3.9 | Z17: 3.9 | AA17: 3.9 | AB17: 3.9 | AC17: 3.9 | AD17: 3.9 | AE17: 3.9 | AF17: 3.9 | AG17: 3.9 | AH17: 3.9 | AI17: 3.9 | AJ17: 3.9 | AK17: 3.9 | AL17: 3.9 | AM17: 3.9 | AN17: 3.9 | AO17: 3.9 | AP17: 3.9 | AQ17: 3.9 | AR17: 3.9
A18: Process technician — cost | B18: =$B$16*B4*B17*'CAPEX'!B4/12 | C18: =$B$16*C4*C17*'CAPEX'!C4/12 | D18: =$B$16*D4*D17*'CAPEX'!D4/12 | E18: =$B$16*E4*E17*'CAPEX'!E4/12 | F18: =$B$16*F4*F17*'CAPEX'!F4/12 | G18: =$B$16*G4*G17*'CAPEX'!G4/12 | H18: =$B$16*H4*H17*'CAPEX'!H4/12 | I18: =$B$16*I4*I17*'CAPEX'!I4/12 | ... AR18: =$B$16*AR4*AR17*'CAPEX'!AR4/12
A19: Operators — annual cost per FTE | B19: 39550
A20: Operators — FTEs | B20: 0 | C20: 0 | D20: 0 | E20: 0 | F20: 0 | G20: 0 | H20: 0 | I20: 0 | J20: 0 | K20: 0 | L20: 0 | M20: 0 | N20: 0 | O20: 0 | P20: 0 | Q20: 3.9 | R20: 3.9 | S20: 3.9 | T20: 7.8 | U20: 7.8 | V20: 7.8 | W20: 7.8 | X20: 7.8 | Y20: 7.8 | Z20: 7.8 | AA20: 7.8 | AB20: 7.8 | AC20: 7.8 | AD20: 7.8 | AE20: 7.8 | AF20: 7.8 | AG20: 7.8 | AH20: 7.8 | AI20: 7.8 | AJ20: 7.8 | AK20: 7.8 | AL20: 7.8 | AM20: 7.8 | AN20: 7.8 | AO20: 7.8 | AP20: 7.8 | AQ20: 7.8 | AR20: 7.8
A21: Operators — cost | B21: =$B$19*B4*B20*'CAPEX'!B4/12 | C21: =$B$19*C4*C20*'CAPEX'!C4/12 | D21: =$B$19*D4*D20*'CAPEX'!D4/12 | E21: =$B$19*E4*E20*'CAPEX'!E4/12 | F21: =$B$19*F4*F20*'CAPEX'!F4/12 | G21: =$B$19*G4*G20*'CAPEX'!G4/12 | H21: =$B$19*H4*H20*'CAPEX'!H4/12 | I21: =$B$19*I4*I20*'CAPEX'!I4/12 | ... AR21: =$B$19*AR4*AR20*'CAPEX'!AR4/12
A22: Maintenance general & relief cover — annual cost per FTE | B22: 45200
A23: Maintenance general & relief cover — FTEs | B23: 0 | C23: 0 | D23: 0 | E23: 0 | F23: 0 | G23: 0 | H23: 0 | I23: 0 | J23: 0 | K23: 0 | L23: 0 | M23: 0 | N23: 0 | O23: 0 | P23: 0 | Q23: 1.95 | R23: 1.95 | S23: 1.95 | T23: 3.9 | U23: 3.9 | V23: 3.9 | W23: 3.9 | X23: 3.9 | Y23: 3.9 | Z23: 3.9 | AA23: 3.9 | AB23: 3.9 | AC23: 3.9 | AD23: 3.9 | AE23: 3.9 | AF23: 3.9 | AG23: 3.9 | AH23: 3.9 | AI23: 3.9 | AJ23: 3.9 | AK23: 3.9 | AL23: 3.9 | AM23: 3.9 | AN23: 3.9 | AO23: 3.9 | AP23: 3.9 | AQ23: 3.9 | AR23: 3.9
A24: Maintenance general & relief cover — cost | B24: =$B$22*B4*B23*'CAPEX'!B4/12 | C24: =$B$22*C4*C23*'CAPEX'!C4/12 | D24: =$B$22*D4*D23*'CAPEX'!D4/12 | E24: =$B$22*E4*E23*'CAPEX'!E4/12 | F24: =$B$22*F4*F23*'CAPEX'!F4/12 | G24: =$B$22*G4*G23*'CAPEX'!G4/12 | H24: =$B$22*H4*H23*'CAPEX'!H4/12 | I24: =$B$22*I4*I23*'CAPEX'!I4/12 | ... AR24: =$B$22*AR4*AR23*'CAPEX'!AR4/12
A25: Admin — annual cost per FTE | B25: 33900
A26: Admin — FTEs | B26: 0 | C26: 0 | D26: 0 | E26: 0 | F26: 0 | G26: 0 | H26: 0 | I26: 0 | J26: 0 | K26: 0 | L26: 0 | M26: 0 | N26: 0 | O26: 0 | P26: 0 | Q26: 0.5 | R26: 0.5 | S26: 0.5 | T26: 1 | U26: 1 | V26: 1 | W26: 1 | X26: 1 | Y26: 1 | Z26: 1 | AA26: 1 | AB26: 1 | AC26: 1 | AD26: 1 | AE26: 1 | AF26: 1 | AG26: 1 | AH26: 1 | AI26: 1 | AJ26: 1 | AK26: 1 | AL26: 1 | AM26: 1 | AN26: 1 | AO26: 1 | AP26: 1 | AQ26: 1 | AR26: 1
A27: Admin — cost | B27: =$B$25*B4*B26*'CAPEX'!B4/12 | C27: =$B$25*C4*C26*'CAPEX'!C4/12 | D27: =$B$25*D4*D26*'CAPEX'!D4/12 | E27: =$B$25*E4*E26*'CAPEX'!E4/12 | F27: =$B$25*F4*F26*'CAPEX'!F4/12 | G27: =$B$25*G4*G26*'CAPEX'!G4/12 | H27: =$B$25*H4*H26*'CAPEX'!H4/12 | I27: =$B$25*I4*I26*'CAPEX'!I4/12 | ... AR27: =$B$25*AR4*AR26*'CAPEX'!AR4/12
A28: Total personnel | B28: =B9+B12+B15+B18+B21+B24+B27 | C28: =C9+C12+C15+C18+C21+C24+C27 | D28: =D9+D12+D15+D18+D21+D24+D27 | E28: =E9+E12+E15+E18+E21+E24+E27 | F28: =F9+F12+F15+F18+F21+F24+F27 | G28: =G9+G12+G15+G18+G21+G24+G27 | H28: =H9+H12+H15+H18+H21+H24+H27 | I28: =I9+I12+I15+I18+I21+I24+I27 | ... AR28: =AR9+AR12+AR15+AR18+AR21+AR24+AR27
A30: Insurance (% of deployed CAPEX) — amount | B30: 0 | C30: 0 | D30: 0 | E30: 0 | F30: 0 | G30: 0 | H30: 0 | I30: 0 | J30: 0 | K30: 0 | L30: 0 | M30: 0 | N30: 0 | O30: 0 | P30: 0 | Q30: 0 | R30: 0 | S30: 0 | T30: 0 | U30: 0 | V30: 0 | W30: 0 | X30: 0 | Y30: 0 | Z30: 0 | AA30: 0 | AB30: 0 | AC30: 0 | AD30: 0 | AE30: 0 | AF30: 0 | AG30: 0 | AH30: 0 | AI30: 0 | AJ30: 0 | AK30: 0 | AL30: 0 | AM30: 0 | AN30: 0 | AO30: 0 | AP30: 0 | AQ30: 0 | AR30: 0
A31: Insurance (% of deployed CAPEX) — % p.a. of deployed CAPEX | B31: 0.015
A32: Insurance (% of deployed CAPEX) — total | B32: =B30*B5+$B$31*'CAPEX'!B40*'CAPEX'!B4/12 | C32: =C30*C5+$B$31*'CAPEX'!C40*'CAPEX'!C4/12 | D32: =D30*D5+$B$31*'CAPEX'!D40*'CAPEX'!D4/12 | E32: =E30*E5+$B$31*'CAPEX'!E40*'CAPEX'!E4/12 | F32: =F30*F5+$B$31*'CAPEX'!F40*'CAPEX'!F4/12 | G32: =G30*G5+$B$31*'CAPEX'!G40*'CAPEX'!G4/12 | H32: =H30*H5+$B$31*'CAPEX'!H40*'CAPEX'!H4/12 | I32: =I30*I5+$B$31*'CAPEX'!I40*'CAPEX'!I4/12 | ... AR32: =AR30*AR5+$B$31*'CAPEX'!AR40*'CAPEX'!AR4/12
A33: Admin overhead — amount | B33: 0 | C33: 0 | D33: 0 | E33: 0 | F33: 0 | G33: 0 | H33: 0 | I33: 0 | J33: 0 | K33: 0 | L33: 0 | M33: 0 | N33: 0 | O33: 0 | P33: 0 | Q33: 10000 | R33: 10000 | S33: 10000 | T33: 10000 | U33: 10000 | V33: 10000 | W33: 10000 | X33: 10000 | Y33: 10000 | Z33: 10000 | AA33: 10000 | AB33: 10000 | AC33: 10000 | AD33: 10000 | AE33: 10000 | AF33: 10000 | AG33: 10000 | AH33: 10000 | AI33: 10000 | AJ33: 10000 | AK33: 10000 | AL33: 120000 | AM33: 120000 | AN33: 120000 | AO33: 120000 | AP33: 120000 | AQ33: 120000 | AR33: 120000
A34: Admin overhead — total | B34: =B33*B5 | C34: =C33*C5 | D34: =D33*D5 | E34: =E33*E5 | F34: =F33*F5 | G34: =G33*G5 | H34: =H33*H5 | I34: =I33*I5 | ... AR34: =AR33*AR5
A35: Land cost (leasing) — amount | B35: 0 | C35: 0 | D35: 0 | E35: 0 | F35: 0 | G35: 0 | H35: 0 | I35: 0 | J35: 0 | K35: 0 | L35: 0 | M35: 0 | N35: 0 | O35: 0 | P35: 0 | Q35: 0 | R35: 0 | S35: 0 | T35: 0 | U35: 0 | V35: 0 | W35: 0 | X35: 0 | Y35: 0 | Z35: 0 | AA35: 0 | AB35: 0 | AC35: 0 | AD35: 0 | AE35: 0 | AF35: 0 | AG35: 0 | AH35: 0 | AI35: 0 | AJ35: 0 | AK35: 0 | AL35: 0 | AM35: 0 | AN35: 0 | AO35: 0 | AP35: 0 | AQ35: 0 | AR35: 0
A36: Land cost (leasing) — total | B36: =B35*B5 | C36: =C35*C5 | D36: =D35*D5 | E36: =E35*E5 | F36: =F35*F5 | G36: =G35*G5 | H36: =H35*H5 | I36: =I35*I5 | ... AR36: =AR35*AR5
A37: Total other OPEX | B37: =B32+B34+B36 | C37: =C32+C34+C36 | D37: =D32+D34+D36 | E37: =E32+E34+E36 | F37: =F32+F34+F36 | G37: =G32+G34+G36 | H37: =H32+H34+H36 | I37: =I32+I34+I36 | ... AR37: =AR32+AR34+AR36

Sheet Financing
A1: Financing instruments
A3: Instrument | B3: Type | C3: Amount | D3: Draw period | E3: Rate | F3: Grace (m) | G3: Tenor (m) | H3: Profile | I3: Upfront fee
A4: FAIIP facility | B4: debt | C4: 10000000 | D4: 2 | E4: 0.04 | F4: 24 | G4: 120 | H4: linear | I4: 0
A5: Grant / subsidy | B5: grant | C5: 2500000 | D5: 6
A6: Equity — Series A | B6: equity | C6: 17000000 | D6: 0
A8: Schedules below are computed by the portal engine and written as values: monthly amortisation cannot be expressed as one row of Excel formulas. Change an instrument in the portal and re-export.
A10: Schedule | B10: Jan-27 | C10: Feb-27 | D10: Mar-27 | E10: Apr-27 | F10: May-27 | G10: Jun-27 | H10: Jul-27 | I10: Aug-27 | J10: Sep-27 | K10: Oct-27 | L10: Nov-27 | M10: Dec-27 | N10: Jan-28 | O10: Feb-28 | P10: Mar-28 | Q10: Apr-28 | R10: May-28 | S10: Jun-28 | T10: Jul-28 | U10: Aug-28 | V10: Sep-28 | W10: Oct-28 | X10: Nov-28 | Y10: Dec-28 | Z10: Jan-29 | AA10: Feb-29 | AB10: Mar-29 | AC10: Apr-29 | AD10: May-29 | AE10: Jun-29 | AF10: Jul-29 | AG10: Aug-29 | AH10: Sep-29 | AI10: Oct-29 | AJ10: Nov-29 | AK10: Dec-29 | AL10: Y4 | AM10: Y5 | AN10: Y6 | AO10: Y7 | AP10: Y8 | AQ10: Y9 | AR10: Y10
A11: Debt drawdown | B11: 0 | C11: 0 | D11: 10000000 | E11: 0 | F11: 0 | G11: 0 | H11: 0 | I11: 0 | J11: 0 | K11: 0 | L11: 0 | M11: 0 | N11: 0 | O11: 0 | P11: 0 | Q11: 0 | R11: 0 | S11: 0 | T11: 0 | U11: 0 | V11: 0 | W11: 0 | X11: 0 | Y11: 0 | Z11: 0 | AA11: 0 | AB11: 0 | AC11: 0 | AD11: 0 | AE11: 0 | AF11: 0 | AG11: 0 | AH11: 0 | AI11: 0 | AJ11: 0 | AK11: 0 | AL11: 0 | AM11: 0 | AN11: 0 | AO11: 0 | AP11: 0 | AQ11: 0 | AR11: 0
A12: Debt repayment | B12: 0 | C12: 0 | D12: 0 | E12: 0 | F12: 0 | G12: 0 | H12: 0 | I12: 0 | J12: 0 | K12: 0 | L12: 0 | M12: 0 | N12: 0 | O12: 0 | P12: 0 | Q12: 0 | R12: 0 | S12: 0 | T12: 0 | U12: 0 | V12: 0 | W12: 0 | X12: 0 | Y12: 0 | Z12: 0 | AA12: 0 | AB12: 104166.67 | AC12: 104166.67 | AD12: 104166.67 | AE12: 104166.67 | AF12: 104166.67 | AG12: 104166.67 | AH12: 104166.67 | AI12: 104166.67 | AJ12: 104166.67 | AK12: 104166.67 | AL12: 1250000 | AM12: 1250000 | AN12: 1250000 | AO12: 1250000 | AP12: 1250000 | AQ12: 1250000 | AR12: 1250000
A13: Interest expense (incl. fees) | B13: 0 | C13: 0 | D13: 33333.333 | E13: 33333.333 | F13: 33333.333 | G13: 33333.333 | H13: 33333.333 | I13: 33333.333 | J13: 33333.333 | K13: 33333.333 | L13: 33333.333 | M13: 33333.333 | N13: 33333.333 | O13: 33333.333 | P13: 33333.333 | Q13: 33333.333 | R13: 33333.333 | S13: 33333.333 | T13: 33333.333 | U13: 33333.333 | V13: 33333.333 | W13: 33333.333 | X13: 33333.333 | Y13: 33333.333 | Z13: 33333.333 | AA13: 33333.333 | AB13: 33333.333 | AC13: 32986.111 | AD13: 32638.889 | AE13: 32291.667 | AF13: 31944.444 | AG13: 31597.222 | AH13: 31250 | AI13: 30902.778 | AJ13: 30555.556 | AK13: 30208.333 | AL13: 335416.67 | AM13: 285416.67 | AN13: 235416.67 | AO13: 185416.67 | AP13: 135416.67 | AQ13: 85416.667 | AR13: 35416.667
A14: Debt balance (closing) | B14: 0 | C14: 0 | D14: 10000000 | E14: 10000000 | F14: 10000000 | G14: 10000000 | H14: 10000000 | I14: 10000000 | J14: 10000000 | K14: 10000000 | L14: 10000000 | M14: 10000000 | N14: 10000000 | O14: 10000000 | P14: 10000000 | Q14: 10000000 | R14: 10000000 | S14: 10000000 | T14: 10000000 | U14: 10000000 | V14: 10000000 | W14: 10000000 | X14: 10000000 | Y14: 10000000 | Z14: 10000000 | AA14: 10000000 | AB14: 9895833.3 | AC14: 9791666.7 | AD14: 9687500 | AE14: 9583333.3 | AF14: 9479166.7 | AG14: 9375000 | AH14: 9270833.3 | AI14: 9166666.7 | AJ14: 9062500 | AK14: 8958333.3 | AL14: 7708333.3 | AM14: 6458333.3 | AN14: 5208333.3 | AO14: 3958333.3 | AP14: 2708333.3 | AQ14: 1458333.3 | AR14: 208333.33
A15: Equity raised | B15: 17000000 | C15: 0 | D15: 0 | E15: 0 | F15: 0 | G15: 0 | H15: 0 | I15: 0 | J15: 0 | K15: 0 | L15: 0 | M15: 0 | N15: 0 | O15: 0 | P15: 0 | Q15: 0 | R15: 0 | S15: 0 | T15: 0 | U15: 0 | V15: 0 | W15: 0 | X15: 0 | Y15: 0 | Z15: 0 | AA15: 0 | AB15: 0 | AC15: 0 | AD15: 0 | AE15: 0 | AF15: 0 | AG15: 0 | AH15: 0 | AI15: 0 | AJ15: 0 | AK15: 0 | AL15: 0 | AM15: 0 | AN15: 0 | AO15: 0 | AP15: 0 | AQ15: 0 | AR15: 0
A16: Grants collected | B16: 0 | C16: 0 | D16: 0 | E16: 0 | F16: 0 | G16: 0 | H16: 2500000 | I16: 0 | J16: 0 | K16: 0 | L16: 0 | M16: 0 | N16: 0 | O16: 0 | P16: 0 | Q16: 0 | R16: 0 | S16: 0 | T16: 0 | U16: 0 | V16: 0 | W16: 0 | X16: 0 | Y16: 0 | Z16: 0 | AA16: 0 | AB16: 0 | AC16: 0 | AD16: 0 | AE16: 0 | AF16: 0 | AG16: 0 | AH16: 0 | AI16: 0 | AJ16: 0 | AK16: 0 | AL16: 0 | AM16: 0 | AN16: 0 | AO16: 0 | AP16: 0 | AQ16: 0 | AR16: 0

Sheet P&L
A1: Profit & loss (EUR)
A3: P&L | B3: Jan-27 | C3: Feb-27 | D3: Mar-27 | E3: Apr-27 | F3: May-27 | G3: Jun-27 | H3: Jul-27 | I3: Aug-27 | J3: Sep-27 | K3: Oct-27 | L3: Nov-27 | M3: Dec-27 | N3: Jan-28 | O3: Feb-28 | P3: Mar-28 | Q3: Apr-28 | R3: May-28 | S3: Jun-28 | T3: Jul-28 | U3: Aug-28 | V3: Sep-28 | W3: Oct-28 | X3: Nov-28 | Y3: Dec-28 | Z3: Jan-29 | AA3: Feb-29 | AB3: Mar-29 | AC3: Apr-29 | AD3: May-29 | AE3: Jun-29 | AF3: Jul-29 | AG3: Aug-29 | AH3: Sep-29 | AI3: Oct-29 | AJ3: Nov-29 | AK3: Dec-29 | AL3: Y4 | AM3: Y5 | AN3: Y6 | AO3: Y7 | AP3: Y8 | AQ3: Y9 | AR3: Y10
A4: Revenue | B4: ='UnitEcon'!B43*'UnitEcon'!B22 | C4: ='UnitEcon'!C43*'UnitEcon'!C22 | D4: ='UnitEcon'!D43*'UnitEcon'!D22 | E4: ='UnitEcon'!E43*'UnitEcon'!E22 | F4: ='UnitEcon'!F43*'UnitEcon'!F22 | G4: ='UnitEcon'!G43*'UnitEcon'!G22 | H4: ='UnitEcon'!H43*'UnitEcon'!H22 | I4: ='UnitEcon'!I43*'UnitEcon'!I22 | ... AR4: ='UnitEcon'!AR43*'UnitEcon'!AR22
A5: COGS — energy | B5: ='UnitEcon'!B42*('UnitEcon'!B33*'UnitEcon'!B34+'UnitEcon'!B35*'UnitEcon'!B36) | C5: ='UnitEcon'!C42*('UnitEcon'!C33*'UnitEcon'!C34+'UnitEcon'!C35*'UnitEcon'!C36) | D5: ='UnitEcon'!D42*('UnitEcon'!D33*'UnitEcon'!D34+'UnitEcon'!D35*'UnitEcon'!D36) | E5: ='UnitEcon'!E42*('UnitEcon'!E33*'UnitEcon'!E34+'UnitEcon'!E35*'UnitEcon'!E36) | F5: ='UnitEcon'!F42*('UnitEcon'!F33*'UnitEcon'!F34+'UnitEcon'!F35*'UnitEcon'!F36) | G5: ='UnitEcon'!G42*('UnitEcon'!G33*'UnitEcon'!G34+'UnitEcon'!G35*'UnitEcon'!G36) | H5: ='UnitEcon'!H42*('UnitEcon'!H33*'UnitEcon'!H34+'UnitEcon'!H35*'UnitEcon'!H36) | I5: ='UnitEcon'!I42*('UnitEcon'!I33*'UnitEcon'!I34+'UnitEcon'!I35*'UnitEcon'!I36) | ... AR5: ='UnitEcon'!AR42*('UnitEcon'!AR33*'UnitEcon'!AR34+'UnitEcon'!AR35*'UnitEcon'!AR36)
A6: COGS — MTS feedstock | B6: ='UnitEcon'!B42*'UnitEcon'!B25*'UnitEcon'!B29/1000 | C6: ='UnitEcon'!C42*'UnitEcon'!C25*'UnitEcon'!C29/1000 | D6: ='UnitEcon'!D42*'UnitEcon'!D25*'UnitEcon'!D29/1000 | E6: ='UnitEcon'!E42*'UnitEcon'!E25*'UnitEcon'!E29/1000 | F6: ='UnitEcon'!F42*'UnitEcon'!F25*'UnitEcon'!F29/1000 | G6: ='UnitEcon'!G42*'UnitEcon'!G25*'UnitEcon'!G29/1000 | H6: ='UnitEcon'!H42*'UnitEcon'!H25*'UnitEcon'!H29/1000 | I6: ='UnitEcon'!I42*'UnitEcon'!I25*'UnitEcon'!I29/1000 | ... AR6: ='UnitEcon'!AR42*'UnitEcon'!AR25*'UnitEcon'!AR29/1000
A7: COGS — reactants | B7: ='UnitEcon'!B42*'UnitEcon'!B26*'UnitEcon'!B30/1000 | C7: ='UnitEcon'!C42*'UnitEcon'!C26*'UnitEcon'!C30/1000 | D7: ='UnitEcon'!D42*'UnitEcon'!D26*'UnitEcon'!D30/1000 | E7: ='UnitEcon'!E42*'UnitEcon'!E26*'UnitEcon'!E30/1000 | F7: ='UnitEcon'!F42*'UnitEcon'!F26*'UnitEcon'!F30/1000 | G7: ='UnitEcon'!G42*'UnitEcon'!G26*'UnitEcon'!G30/1000 | H7: ='UnitEcon'!H42*'UnitEcon'!H26*'UnitEcon'!H30/1000 | I7: ='UnitEcon'!I42*'UnitEcon'!I26*'UnitEcon'!I30/1000 | ... AR7: ='UnitEcon'!AR42*'UnitEcon'!AR26*'UnitEcon'!AR30/1000
A8: COGS — residue disposal | B8: ='UnitEcon'!B42*'UnitEcon'!B27*'UnitEcon'!B31/1000 | C8: ='UnitEcon'!C42*'UnitEcon'!C27*'UnitEcon'!C31/1000 | D8: ='UnitEcon'!D42*'UnitEcon'!D27*'UnitEcon'!D31/1000 | E8: ='UnitEcon'!E42*'UnitEcon'!E27*'UnitEcon'!E31/1000 | F8: ='UnitEcon'!F42*'UnitEcon'!F27*'UnitEcon'!F31/1000 | G8: ='UnitEcon'!G42*'UnitEcon'!G27*'UnitEcon'!G31/1000 | H8: ='UnitEcon'!H42*'UnitEcon'!H27*'UnitEcon'!H31/1000 | I8: ='UnitEcon'!I42*'UnitEcon'!I27*'UnitEcon'!I31/1000 | ... AR8: ='UnitEcon'!AR42*'UnitEcon'!AR27*'UnitEcon'!AR31/1000
A9: COGS — water | B9: ='UnitEcon'!B42*'UnitEcon'!B28*'UnitEcon'!B32/1000 | C9: ='UnitEcon'!C42*'UnitEcon'!C28*'UnitEcon'!C32/1000 | D9: ='UnitEcon'!D42*'UnitEcon'!D28*'UnitEcon'!D32/1000 | E9: ='UnitEcon'!E42*'UnitEcon'!E28*'UnitEcon'!E32/1000 | F9: ='UnitEcon'!F42*'UnitEcon'!F28*'UnitEcon'!F32/1000 | G9: ='UnitEcon'!G42*'UnitEcon'!G28*'UnitEcon'!G32/1000 | H9: ='UnitEcon'!H42*'UnitEcon'!H28*'UnitEcon'!H32/1000 | I9: ='UnitEcon'!I42*'UnitEcon'!I28*'UnitEcon'!I32/1000 | ... AR9: ='UnitEcon'!AR42*'UnitEcon'!AR28*'UnitEcon'!AR32/1000
A10: COGS — maintenance | B10: ='UnitEcon'!B37*'CAPEX'!B40*'CAPEX'!B4*'UnitEcon'!B41/12 | C10: ='UnitEcon'!C37*'CAPEX'!C40*'CAPEX'!C4*'UnitEcon'!C41/12 | D10: ='UnitEcon'!D37*'CAPEX'!D40*'CAPEX'!D4*'UnitEcon'!D41/12 | E10: ='UnitEcon'!E37*'CAPEX'!E40*'CAPEX'!E4*'UnitEcon'!E41/12 | F10: ='UnitEcon'!F37*'CAPEX'!F40*'CAPEX'!F4*'UnitEcon'!F41/12 | G10: ='UnitEcon'!G37*'CAPEX'!G40*'CAPEX'!G4*'UnitEcon'!G41/12 | H10: ='UnitEcon'!H37*'CAPEX'!H40*'CAPEX'!H4*'UnitEcon'!H41/12 | I10: ='UnitEcon'!I37*'CAPEX'!I40*'CAPEX'!I4*'UnitEcon'!I41/12 | ... AR10: ='UnitEcon'!AR37*'CAPEX'!AR40*'CAPEX'!AR4*'UnitEcon'!AR41/12
A11: Total COGS | B11: =B5+B6+B7+B8+B9+B10 | C11: =C5+C6+C7+C8+C9+C10 | D11: =D5+D6+D7+D8+D9+D10 | E11: =E5+E6+E7+E8+E9+E10 | F11: =F5+F6+F7+F8+F9+F10 | G11: =G5+G6+G7+G8+G9+G10 | H11: =H5+H6+H7+H8+H9+H10 | I11: =I5+I6+I7+I8+I9+I10 | ... AR11: =AR5+AR6+AR7+AR8+AR9+AR10
A12: Gross margin | B12: =B4-B11 | C12: =C4-C11 | D12: =D4-D11 | E12: =E4-E11 | F12: =F4-F11 | G12: =G4-G11 | H12: =H4-H11 | I12: =I4-I11 | ... AR12: =AR4-AR11
A13: OPEX — personnel | B13: ='OPEX'!B28 | C13: ='OPEX'!C28 | D13: ='OPEX'!D28 | E13: ='OPEX'!E28 | F13: ='OPEX'!F28 | G13: ='OPEX'!G28 | H13: ='OPEX'!H28 | I13: ='OPEX'!I28 | ... AR13: ='OPEX'!AR28
A14: OPEX — other | B14: ='OPEX'!B37 | C14: ='OPEX'!C37 | D14: ='OPEX'!D37 | E14: ='OPEX'!E37 | F14: ='OPEX'!F37 | G14: ='OPEX'!G37 | H14: ='OPEX'!H37 | I14: ='OPEX'!I37 | ... AR14: ='OPEX'!AR37
A15: Total OPEX | B15: =B13+B14 | C15: =C13+C14 | D15: =D13+D14 | E15: =E13+E14 | F15: =F13+F14 | G15: =G13+G14 | H15: =H13+H14 | I15: =I13+I14 | ... AR15: =AR13+AR14
A16: EBITDA | B16: =B12-B15 | C16: =C12-C15 | D16: =D12-D15 | E16: =E12-E15 | F16: =F12-F15 | G16: =G12-G15 | H16: =H12-H15 | I16: =I12-I15 | ... AR16: =AR12-AR15
A17: Depreciation | B17: ='CAPEX'!B41 | C17: ='CAPEX'!C41 | D17: ='CAPEX'!D41 | E17: ='CAPEX'!E41 | F17: ='CAPEX'!F41 | G17: ='CAPEX'!G41 | H17: ='CAPEX'!H41 | I17: ='CAPEX'!I41 | ... AR17: ='CAPEX'!AR41
A18: EBIT | B18: =B16-B17 | C18: =C16-C17 | D18: =D16-D17 | E18: =E16-E17 | F18: =F16-F17 | G18: =G16-G17 | H18: =H16-H17 | I18: =I16-I17 | ... AR18: =AR16-AR17
A19: Interest expense | B19: ='Financing'!B13 | C19: ='Financing'!C13 | D19: ='Financing'!D13 | E19: ='Financing'!E13 | F19: ='Financing'!F13 | G19: ='Financing'!G13 | H19: ='Financing'!H13 | I19: ='Financing'!I13 | ... AR19: ='Financing'!AR13
A20: Grant income | B20: ='Financing'!B16 | C20: ='Financing'!C16 | D20: ='Financing'!D16 | E20: ='Financing'!E16 | F20: ='Financing'!F16 | G20: ='Financing'!G16 | H20: ='Financing'!H16 | I20: ='Financing'!I16 | ... AR20: ='Financing'!AR16
A21: Profit before tax | B21: =B18-B19+B20 | C21: =C18-C19+C20 | D21: =D18-D19+D20 | E21: =E18-E19+E20 | F21: =F18-F19+F20 | G21: =G18-G19+G20 | H21: =H18-H19+H20 | I21: =I18-I19+I20 | ... AR21: =AR18-AR19+AR20
A22: Loss carry-forward pool (closing) | B22: =MAX(0,0-B21) | C22: =MAX(0,B22-C21) | D22: =MAX(0,C22-D21) | E22: =MAX(0,D22-E21) | F22: =MAX(0,E22-F21) | G22: =MAX(0,F22-G21) | H22: =MAX(0,G22-H21) | I22: =MAX(0,H22-I21) | J22: =MAX(0,I22-J21) | ... AR22: =MAX(0,AQ22-AR21)
A23: Income tax | B23: =MAX(0,B21-0)*'Parameters'!$B$6 | C23: =MAX(0,C21-B22)*'Parameters'!$B$6 | D23: =MAX(0,D21-C22)*'Parameters'!$B$6 | E23: =MAX(0,E21-D22)*'Parameters'!$B$6 | F23: =MAX(0,F21-E22)*'Parameters'!$B$6 | G23: =MAX(0,G21-F22)*'Parameters'!$B$6 | H23: =MAX(0,H21-G22)*'Parameters'!$B$6 | I23: =MAX(0,I21-H22)*'Parameters'!$B$6 | J23: =MAX(0,J21-I22)*'Parameters'!$B$6 | ... AR23: =MAX(0,AR21-AQ22)*'Parameters'!$B$6
A24: Net income | B24: =B21-B23 | C24: =C21-C23 | D24: =D21-D23 | E24: =E21-E23 | F24: =F21-F23 | G24: =G21-G23 | H24: =H21-H23 | I24: =I21-I23 | ... AR24: =AR21-AR23

Sheet Cashflow
A1: Cash flow (EUR)
A3: Cash flow | B3: Jan-27 | C3: Feb-27 | D3: Mar-27 | E3: Apr-27 | F3: May-27 | G3: Jun-27 | H3: Jul-27 | I3: Aug-27 | J3: Sep-27 | K3: Oct-27 | L3: Nov-27 | M3: Dec-27 | N3: Jan-28 | O3: Feb-28 | P3: Mar-28 | Q3: Apr-28 | R3: May-28 | S3: Jun-28 | T3: Jul-28 | U3: Aug-28 | V3: Sep-28 | W3: Oct-28 | X3: Nov-28 | Y3: Dec-28 | Z3: Jan-29 | AA3: Feb-29 | AB3: Mar-29 | AC3: Apr-29 | AD3: May-29 | AE3: Jun-29 | AF3: Jul-29 | AG3: Aug-29 | AH3: Sep-29 | AI3: Oct-29 | AJ3: Nov-29 | AK3: Dec-29 | AL3: Y4 | AM3: Y5 | AN3: Y6 | AO3: Y7 | AP3: Y8 | AQ3: Y9 | AR3: Y10
A4: Days in period | B4: 30.416667 | C4: 30.416667 | D4: 30.416667 | E4: 30.416667 | F4: 30.416667 | G4: 30.416667 | H4: 30.416667 | I4: 30.416667 | J4: 30.416667 | K4: 30.416667 | L4: 30.416667 | M4: 30.416667 | N4: 30.416667 | O4: 30.416667 | P4: 30.416667 | Q4: 30.416667 | R4: 30.416667 | S4: 30.416667 | T4: 30.416667 | U4: 30.416667 | V4: 30.416667 | W4: 30.416667 | X4: 30.416667 | Y4: 30.416667 | Z4: 30.416667 | AA4: 30.416667 | AB4: 30.416667 | AC4: 30.416667 | AD4: 30.416667 | AE4: 30.416667 | AF4: 30.416667 | AG4: 30.416667 | AH4: 30.416667 | AI4: 30.416667 | AJ4: 30.416667 | AK4: 30.416667 | AL4: 365 | AM4: 365 | AN4: 365 | AO4: 365 | AP4: 365 | AQ4: 365 | AR4: 365
A5: Accounts receivable (closing) | B5: =IF(B4=0,0,'P&L'!B4/B4*'Parameters'!$B$7) | C5: =IF(C4=0,0,'P&L'!C4/C4*'Parameters'!$B$7) | D5: =IF(D4=0,0,'P&L'!D4/D4*'Parameters'!$B$7) | E5: =IF(E4=0,0,'P&L'!E4/E4*'Parameters'!$B$7) | F5: =IF(F4=0,0,'P&L'!F4/F4*'Parameters'!$B$7) | G5: =IF(G4=0,0,'P&L'!G4/G4*'Parameters'!$B$7) | H5: =IF(H4=0,0,'P&L'!H4/H4*'Parameters'!$B$7) | I5: =IF(I4=0,0,'P&L'!I4/I4*'Parameters'!$B$7) | ... AR5: =IF(AR4=0,0,'P&L'!AR4/AR4*'Parameters'!$B$7)
A6: Accounts payable (closing) | B6: =IF(B4=0,0,('P&L'!B11+'P&L'!B15)/B4*'Parameters'!$B$8) | C6: =IF(C4=0,0,('P&L'!C11+'P&L'!C15)/C4*'Parameters'!$B$8) | D6: =IF(D4=0,0,('P&L'!D11+'P&L'!D15)/D4*'Parameters'!$B$8) | E6: =IF(E4=0,0,('P&L'!E11+'P&L'!E15)/E4*'Parameters'!$B$8) | F6: =IF(F4=0,0,('P&L'!F11+'P&L'!F15)/F4*'Parameters'!$B$8) | G6: =IF(G4=0,0,('P&L'!G11+'P&L'!G15)/G4*'Parameters'!$B$8) | H6: =IF(H4=0,0,('P&L'!H11+'P&L'!H15)/H4*'Parameters'!$B$8) | I6: =IF(I4=0,0,('P&L'!I11+'P&L'!I15)/I4*'Parameters'!$B$8) | ... AR6: =IF(AR4=0,0,('P&L'!AR11+'P&L'!AR15)/AR4*'Parameters'!$B$8)
A7: Change in receivables | B7: =-B5 | C7: =-(C5-B5) | D7: =-(D5-C5) | E7: =-(E5-D5) | F7: =-(F5-E5) | G7: =-(G5-F5) | H7: =-(H5-G5) | I7: =-(I5-H5) | J7: =-(J5-I5) | ... AR7: =-(AR5-AQ5)
A8: Change in payables | B8: =B6 | C8: =C6-B6 | D8: =D6-C6 | E8: =E6-D6 | F8: =F6-E6 | G8: =G6-F6 | H8: =H6-G6 | I8: =I6-H6 | J8: =J6-I6 | ... AR8: =AR6-AQ6
A9: Other working capital | B9: 0 | C9: 0 | D9: 0 | E9: 0 | F9: 0 | G9: 0 | H9: 0 | I9: 0 | J9: 0 | K9: 0 | L9: 0 | M9: 0 | N9: 0 | O9: 0 | P9: 0 | Q9: 0 | R9: 0 | S9: 0 | T9: 0 | U9: 0 | V9: 0 | W9: 0 | X9: 0 | Y9: 0 | Z9: 0 | AA9: 0 | AB9: 0 | AC9: 0 | AD9: 0 | AE9: 0 | AF9: 0 | AG9: 0 | AH9: 0 | AI9: 0 | AJ9: 0 | AK9: 0 | AL9: 0 | AM9: 0 | AN9: 0 | AO9: 0 | AP9: 0 | AQ9: 0 | AR9: 0
A10: Operating cash flow (CFO) | B10: ='P&L'!B24+'P&L'!B17-'P&L'!B20+B7+B8+B9 | C10: ='P&L'!C24+'P&L'!C17-'P&L'!C20+C7+C8+C9 | D10: ='P&L'!D24+'P&L'!D17-'P&L'!D20+D7+D8+D9 | E10: ='P&L'!E24+'P&L'!E17-'P&L'!E20+E7+E8+E9 | F10: ='P&L'!F24+'P&L'!F17-'P&L'!F20+F7+F8+F9 | G10: ='P&L'!G24+'P&L'!G17-'P&L'!G20+G7+G8+G9 | H10: ='P&L'!H24+'P&L'!H17-'P&L'!H20+H7+H8+H9 | I10: ='P&L'!I24+'P&L'!I17-'P&L'!I20+I7+I8+I9 | ... AR10: ='P&L'!AR24+'P&L'!AR17-'P&L'!AR20+AR7+AR8+AR9
A11: Investing cash flow (CFI) | B11: =-'CAPEX'!B39 | C11: =-'CAPEX'!C39 | D11: =-'CAPEX'!D39 | E11: =-'CAPEX'!E39 | F11: =-'CAPEX'!F39 | G11: =-'CAPEX'!G39 | H11: =-'CAPEX'!H39 | I11: =-'CAPEX'!I39 | ... AR11: =-'CAPEX'!AR39
A12: Debt drawdown | B12: ='Financing'!B11 | C12: ='Financing'!C11 | D12: ='Financing'!D11 | E12: ='Financing'!E11 | F12: ='Financing'!F11 | G12: ='Financing'!G11 | H12: ='Financing'!H11 | I12: ='Financing'!I11 | ... AR12: ='Financing'!AR11
A13: Debt repayment | B13: =-'Financing'!B12 | C13: =-'Financing'!C12 | D13: =-'Financing'!D12 | E13: =-'Financing'!E12 | F13: =-'Financing'!F12 | G13: =-'Financing'!G12 | H13: =-'Financing'!H12 | I13: =-'Financing'!I12 | ... AR13: =-'Financing'!AR12
A14: Equity raised | B14: ='Financing'!B15 | C14: ='Financing'!C15 | D14: ='Financing'!D15 | E14: ='Financing'!E15 | F14: ='Financing'!F15 | G14: ='Financing'!G15 | H14: ='Financing'!H15 | I14: ='Financing'!I15 | ... AR14: ='Financing'!AR15
A15: Grants collected | B15: ='Financing'!B16 | C15: ='Financing'!C16 | D15: ='Financing'!D16 | E15: ='Financing'!E16 | F15: ='Financing'!F16 | G15: ='Financing'!G16 | H15: ='Financing'!H16 | I15: ='Financing'!I16 | ... AR15: ='Financing'!AR16
A16: Financing cash flow (CFF) | B16: =B12+B13+B14+B15 | C16: =C12+C13+C14+C15 | D16: =D12+D13+D14+D15 | E16: =E12+E13+E14+E15 | F16: =F12+F13+F14+F15 | G16: =G12+G13+G14+G15 | H16: =H12+H13+H14+H15 | I16: =I12+I13+I14+I15 | ... AR16: =AR12+AR13+AR14+AR15
A17: Net cash flow | B17: =B10+B11+B16 | C17: =C10+C11+C16 | D17: =D10+D11+D16 | E17: =E10+E11+E16 | F17: =F10+F11+F16 | G17: =G10+G11+G16 | H17: =H10+H11+H16 | I17: =I10+I11+I16 | ... AR17: =AR10+AR11+AR16
A18: Opening cash | B18: ='Parameters'!$B$12 | C18: =B19 | D18: =C19 | E18: =D19 | F18: =E19 | G18: =F19 | H18: =G19 | I18: =H19 | J18: =I19 | ... AR18: =AQ19
A19: Closing cash | B19: =B18+B17 | C19: =C18+C17 | D19: =D18+D17 | E19: =E18+E17 | F19: =F18+F17 | G19: =G18+G17 | H19: =H18+H17 | I19: =I18+I17 | ... AR19: =AR18+AR17
A21: Unlevered PBT (EBIT + grants) | B21: ='P&L'!B18+'P&L'!B20 | C21: ='P&L'!C18+'P&L'!C20 | D21: ='P&L'!D18+'P&L'!D20 | E21: ='P&L'!E18+'P&L'!E20 | F21: ='P&L'!F18+'P&L'!F20 | G21: ='P&L'!G18+'P&L'!G20 | H21: ='P&L'!H18+'P&L'!H20 | I21: ='P&L'!I18+'P&L'!I20 | ... AR21: ='P&L'!AR18+'P&L'!AR20
A22: Unlevered loss carry-forward pool | B22: =MAX(0,0-B21) | C22: =MAX(0,B22-C21) | D22: =MAX(0,C22-D21) | E22: =MAX(0,D22-E21) | F22: =MAX(0,E22-F21) | G22: =MAX(0,F22-G21) | H22: =MAX(0,G22-H21) | I22: =MAX(0,H22-I21) | J22: =MAX(0,I22-J21) | ... AR22: =MAX(0,AQ22-AR21)
